Workbook

Sheet تست کور
A1: کد | B1: گروه | C1: دشواری | D1: متن تراکنش (برای گفتن یا تایپ) | E1: وابسته به | F1: مسیر مورد انتظار | G1: خروجی حساب‌یار (پرکردنی) | H1: نتیجه (پرکردنی) | I1: ثبت اشتباه با اطمینان؟ (پرکردنی) | J1: یادداشت تستر (پرکردنی)
A2: R001 | B2: روزانه | C2: آسان | D2: امروز هشت میلیون و پانصد هزار تومان فروش نقدی داشتیم، پولش تو صندوقه. | F2: ثبت خودکار یا تأیید ساده
A3: R002 | B3: روزانه | C3: آسان | D3: بابت نصب و راه‌اندازی دستگاه برای شرکت آریا تجارت دو میلیون و ششصد هزار تومان به حساب ملت واریز شد. | F3: ثبت خودکار یا تأیید ساده
A4: R003 | B4: روزانه | C4: آسان | D4: قبض برق مغازه یک میلیون و دویست هزار تومن از ملت پرداخت شد. | F4: ثبت خودکار یا تأیید ساده
A5: R004 | B5: روزانه | C5: آسان | D5: برای تبلیغات اینستاگرام چهار میلیون از ملت دادیم. | F5: ثبت خودکار یا تأیید ساده
A6: R005 | B6: روزانه | C6: آسان | D6: ۳۵۰ هزار تومن ناهار بچه‌ها رو از صندوق دادیم. | F6: ثبت خودکار یا تأیید ساده
A7: R006 | B7: روزانه | C7: آسان | D7: کرایهٔ باربری ارسال سفارش به کرج ۸۰۰ هزار تومن نقد دادیم. | F7: ثبت خودکار یا تأیید ساده
A8: R007 | B8: روزانه | C8: آسان | D8: بنزین ماشین شرکت ۶۰۰ هزار تومن، کارت به کارت از تجارت. | F8: ثبت خودکار یا تأیید ساده
A9: R008 | B9: روزانه | C9: متوسط | D9: اشتراک ماهانهٔ نرم‌افزار CRM یک میلیون و دویست از ملت کم شد. | F9: ثبت خودکار یا تأیید ساده
A10: R009 | B10: روزانه | C10: آسان | D10: کارمزد انتقال پایا ۱۲ هزار تومن از حساب ملت کسر شد. | F10: ثبت خودکار یا تأیید ساده
A11: R010 | B11: روزانه | C11: آسان | D11: بانک ملت یک میلیون و چهارصد سود سپردهٔ این ماه رو واریز کرد. | F11: ثبت خودکار یا تأیید ساده
A12: R011 | B12: روزانه | C12: آسان | D12: کاغذ A4 و تونر پرینتر ۹۵۰ هزار تومن خریدیم، نقدی. | F12: ثبت خودکار یا تأیید ساده
A13: R012 | B13: روزانه | C13: آسان | D13: حق‌الزحمهٔ طراح لوگو پنج میلیون از تجارت پرداخت شد. | F13: ثبت خودکار یا تأیید ساده
... A33: R032 | B33: بدهی و طلب باز | C33: سخت | D33: آقای کاظمی ۱۲ میلیون نسیه از ما جنس برد. | F33: ثبت خودکار یا تأیید ساده
A34: R033 | B34: تسویه | C34: متوسط | D34: شرکت آریا تجارت ۲۵ میلیون بابت فاکتور فروش قبلی واریز کرد به ملت. | E34: R026 | F34: ثبت خودکار یا تأیید ساده
A35: R034 | B35: تسویه | C35: متوسط | D35: ۱۵ میلیون از ۱۸ میلیون بدهی پخش گلستان رو از تجارت دادیم. | E35: R027 | F35: ثبت خودکار یا تأیید ساده
A36: R035 | B36: تسویه | C36: سخت | D36: قبض برق مهر که اومده بود رو امروز از ملت پرداخت کردیم، ۴ میلیون. | E36: R025 | F36: ثبت خودکار یا تأیید ساده
A37: R036 | B37: تسویه | C37: سخت | D37: آقای کاظمی ۵ میلیون از بدهیش رو نقد آورد. | E37: R032 | F37: ثبت خودکار یا تأیید ساده
A38: R037 | B38: تسویه | C38: متوسط | D38: ۳ میلیون آقای رضایی بابت تعمیر کولر رو از صندوق دادیم. | E38: R028 | F38: ثبت خودکار یا تأیید ساده
A39: R038 | B39: تسویه | C39: سخت | D39: ۱۰ میلیون بدهی قبلی به آقای نوری رو تسویه کردیم از ملت. | F39: صف حسابدار ← «تحلیل کن»
A40: R039 | B40: شریک و مالک | C40: سخت | D40: شریکمون آقای سعیدی ۵۰ میلیون گذاشت تو کار و ریخت به ملت؛ گفت هر وقت لازم شد پسش میدیم. | F40: صف حسابدار ← «تحلیل کن»
A41: R040 | B41: شریک و مالک | C41: سخت | D41: خانم کریمی شریکمون ۲۰ میلیون ریخت به حساب شرکت. | F41: صف حسابدار ← «تحلیل کن»
A42: R041 | B42: شریک و مالک | C42: متوسط | D42: مجمع افزایش سرمایه رو تصویب کرد و آقای سعیدی ۱۰۰ میلیون آوردهٔ سرمایه ریخت به ملت. | F42: صف حسابدار ← «تحلیل کن»
A43: R042 | B43: شریک و مالک | C43: متوسط | D43: آقای سعیدی ۸ میلیون از حساب تجارت برای خرج شخصی خودش برداشت. | F43: صف حسابدار ← «تحلیل کن»
A44: R043 | B44: شریک و مالک | C44: سخت | D44: قبض تلفن دفتر رو خانم کریمی از جیب خودش داد، ۷۰۰ هزار تومن. | F44: کارت سؤال، بعد ثبت
A45: R044 | B45: شریک و مالک | C45: متوسط | D45: ۲۰ میلیون از پولی که آقای سعیدی گذاشته بود رو بهش پس دادیم از ملت. | E45: R039 | F45: صف حسابدار ← «تحلیل کن»
A46: R045 | B46: شریک و مالک | C46: متوسط | D46: آقای سعیدی ۸ میلیونی که برداشته بود رو برگردوند به تجارت. | E46: R042 | F46: صف حسابدار ← «تحلیل کن»
A47: R046 | B47: شریک و مالک | C47: سخت | D47: شریکم ۱۰ میلیون برداشت کرد، گفت پسش میده. | F47: صف حسابدار ← «تحلیل کن»
A48: R047 | B48: شریک و مالک | C48: سخت | D48: برادرم که شریکمه ده میلیون به حساب شرکت ریخت برای خرید مواد اولیه. | F48: صف حسابدار ← «تحلیل کن»
A49: R048 | B49: دارایی ثابت و تعمیر | C49: سخت | D49: یه کلید برق ۴۵۰ هزار تومانی برای تابلوی برق دفتر خریدیم که کلید سوختهٔ قبلی رو عوض کردیم؛ نقد از صندوق. | F49: ثبت خودکار یا تأیید ساده
A50: R049 | B50: دارایی ثابت و تعمیر | C50: سخت | D50: یه پرینتر لیزری ۲۵ میلیون تومانی برای دفتر از حساب ملت خریدیم | F50: صف حسابدار ← «تحلیل کن»
A51: R050 | B51: دارایی ثابت و تعمیر | C51: سخت | D51: تابلوی برق ساختمان رو با ۲۲ میلیون تومان کامل بازسازی و ارتقا دادیم؛ نقد از صندوق. | F51: صف حسابدار ← «تحلیل کن»
A52: R051 | B52: دارایی ثابت و تعمیر | C52: متوسط | D52: لپ‌تاپ ۱۸ میلیونی برای حسابدار از تجارت خریدیم. | F52: کارت سؤال، بعد ثبت
A53: R052 | B53: دارایی ثابت و تعمیر | C53: متوسط | D53: ماشین شرکت تصادف کرد، صافکاری و رنگ ۹ میلیون شد، از ملت دادیم. | F53: ثبت خودکار یا تأیید ساده
A54: R053 | B54: دارایی ثابت و تعمیر | C54: سخت | D54: موتور کولر سوخت، یه موتور نو ۶ میلیونی جاش گذاشتیم، نقد. | F54: ثبت خودکار یا تأیید ساده
A55: R054 | B55: پیش‌پرداخت، پیش‌دریافت، ودیعه | C55: سخت | D55: اجارهٔ شش‌ماههٔ دفتر رو ۳۶ میلیون تومان پیش‌پرداخت کردیم از بانک ملت. | F55: صف حسابدار ← «تحلیل کن»
A56: R055 | B56: پیش‌پرداخت، پیش‌دریافت، ودیعه | C56: سخت | D56: بیمهٔ آتش‌سوزی انبار یک‌ساله ۱۲ میلیون از ملت. | F56: صف حسابدار ← «تحلیل کن»
A57: R056 | B57: پیش‌پرداخت، پیش‌دریافت، ودیعه | C57: سخت | D57: بیمهٔ حوادث کارگران کارگاه یک‌ساله ۱۲ میلیون تومان از بانک ملت پرداخت شد. | F57: صف حسابدار ← «تحلیل کن»
A58: R057 | B58: پیش‌پرداخت، پیش‌دریافت، ودیعه | C58: سخت | D58: مشتری ۱۵ میلیون پیش‌پرداخت داد برای پروژه‌ای که ماه بعد شروع می‌کنیم، ریخت به ملت. | F58: صف حسابدار ← «تحلیل کن»
A59: R058 | B59: پیش‌پرداخت، پیش‌دریافت، ودیعه | C59: سخت | D59: ۵۰ میلیون ودیعهٔ اجارهٔ انبار جدید رو به موجر دادیم از ملت؛ موقع تخلیه پس می‌ده. | F59: صف حسابدار ← «تحلیل کن»
...

Sheet کلید پاسخ کامل
A1: کد | B1: گروه | C1: متن تراکنش | D1: مسیر مورد انتظار | E1: بدهکار | F1: بستانکار | G1: مبلغ سند (تومان) | H1: سؤال‌های مورد انتظار | I1: جواب‌هایی که بده | J1: توضیح ثبت درست | K1: تله / چرا سخت است
A2: R001 | B2: روزانه | C2: امروز هشت میلیون و پانصد هزار تومان فروش نقدی داشتیم، پولش تو صندوقه. | D2: ثبت خودکار یا تأیید ساده | E2: صندوق — ۸٬۵۰۰٬۰۰۰ | F2: فروش — ۸٬۵۰۰٬۰۰۰ | G2: 8500000 | K2: عدد با حروف
A3: R002 | B3: روزانه | C3: بابت نصب و راه‌اندازی دستگاه برای شرکت آریا تجارت دو میلیون و ششصد هزار تومان به حساب ملت واریز شد. | D3: ثبت خودکار یا تأیید ساده | E3: جاری ملت — ۲٬۶۰۰٬۰۰۰ | F3: خدمات — ۲٬۶۰۰٬۰۰۰ | G3: 2600000 | J3: طرف‌حساب: شرکت آریا تجارت. | K3: درآمد خدمات، نه فروش کالا
A4: R003 | B4: روزانه | C4: قبض برق مغازه یک میلیون و دویست هزار تومن از ملت پرداخت شد. | D4: ثبت خودکار یا تأیید ساده | E4: قبوض — ۱٬۲۰۰٬۰۰۰ | F4: جاری ملت — ۱٬۲۰۰٬۰۰۰ | G4: 1200000
A5: R004 | B5: روزانه | C5: برای تبلیغات اینستاگرام چهار میلیون از ملت دادیم. | D5: ثبت خودکار یا تأیید ساده | E5: تبلیغات و بازاریابی — ۴٬۰۰۰٬۰۰۰ | F5: جاری ملت — ۴٬۰۰۰٬۰۰۰ | G5: 4000000
A6: R005 | B6: روزانه | C6: ۳۵۰ هزار تومن ناهار بچه‌ها رو از صندوق دادیم. | D6: ثبت خودکار یا تأیید ساده | E6: خوراک — ۳۵۰٬۰۰۰ | F6: صندوق — ۳۵۰٬۰۰۰ | G6: 350000
A7: R006 | B7: روزانه | C7: کرایهٔ باربری ارسال سفارش به کرج ۸۰۰ هزار تومن نقد دادیم. | D7: ثبت خودکار یا تأیید ساده | E7: حمل‌ونقل — ۸۰۰٬۰۰۰ | F7: صندوق — ۸۰۰٬۰۰۰ | G7: 800000
A8: R007 | B8: روزانه | C8: بنزین ماشین شرکت ۶۰۰ هزار تومن، کارت به کارت از تجارت. | D8: ثبت خودکار یا تأیید ساده | E8: سوخت و ایاب‌وذهاب — ۶۰۰٬۰۰۰ | F8: جاری تجارت — ۶۰۰٬۰۰۰ | G8: 600000
A9: R008 | B9: روزانه | C9: اشتراک ماهانهٔ نرم‌افزار CRM یک میلیون و دویست از ملت کم شد. | D9: ثبت خودکار یا تأیید ساده | E9: نرم‌افزار و اشتراک — ۱٬۲۰۰٬۰۰۰ | F9: جاری ملت — ۱٬۲۰۰٬۰۰۰ | G9: 1200000 | K9: اشتراک یک‌ماهه هزینهٔ همین ماه است، نه پیش‌پرداخت
A10: R009 | B10: روزانه | C10: کارمزد انتقال پایا ۱۲ هزار تومن از حساب ملت کسر شد. | D10: ثبت خودکار یا تأیید ساده | E10: کارمزد بانکی — ۱۲٬۰۰۰ | F10: جاری ملت — ۱۲٬۰۰۰ | G10: 12000
A11: R010 | B11: روزانه | C11: بانک ملت یک میلیون و چهارصد سود سپردهٔ این ماه رو واریز کرد. | D11: ثبت خودکار یا تأیید ساده | E11: جاری ملت — ۱٬۴۰۰٬۰۰۰ | F11: سایر درآمدها — ۱٬۴۰۰٬۰۰۰ | G11: 1400000 | K11: سود سپرده درآمد غیرعملیاتی است، نه فروش
A12: R011 | B12: روزانه | C12: کاغذ A4 و تونر پرینتر ۹۵۰ هزار تومن خریدیم، نقدی. | D12: ثبت خودکار یا تأیید ساده | E12: ملزومات اداری — ۹۵۰٬۰۰۰ | F12: صندوق — ۹۵۰٬۰۰۰ | G12: 950000
A13: R012 | B13: روزانه | C13: حق‌الزحمهٔ طراح لوگو پنج میلیون از تجارت پرداخت شد. | D13: ثبت خودکار یا تأیید ساده | E13: پیمانکار و خدمات بیرونی — ۵٬۰۰۰٬۰۰۰ | F13: جاری تجارت — ۵٬۰۰۰٬۰۰۰ | G13: 5000000 | K13: «حق‌الزحمه» واژهٔ درآمد خدمات است؛ این‌جا پول رفته
A14: R013 | B14: روزانه | C14: هزینهٔ دورهٔ آموزش اکسل برای دو نفر از کارمندا ۳ میلیون از ملت. | D14: ثبت خودکار یا تأیید ساده | E14: آموزش — ۳٬۰۰۰٬۰۰۰ | F14: جاری ملت — ۳٬۰۰۰٬۰۰۰ | G14: 3000000
A15: R014 | B15: روزانه | C15: اجارهٔ همین ماه دفتر ۱۵ میلیون به آقای اسدی از ملت واریز شد. | D15: ثبت خودکار یا تأیید ساده | E15: اجاره — ۱۵٬۰۰۰٬۰۰۰ | F15: جاری ملت — ۱۵٬۰۰۰٬۰۰۰ | G15: 15000000 | J15: طرف‌حساب: آقای اسدی. | K15: اجارهٔ یک‌ماهه هزینه است، نه پیش‌پرداخت
A16: R015 | B16: روزانه | C16: دو میلیون و هفتصد پول پروژهٔ طراحی سایت رو از مشتری نقد گرفتیم. | D16: ثبت خودکار یا تأیید ساده | E16: صندوق — ۲٬۷۰۰٬۰۰۰ | F16: پروژه و دستمزد — ۲٬۷۰۰٬۰۰۰ | G16: 2700000
A17: R016 | B17: گفتار و تایپ | C17: امروز 12 میلیون تومن جنس فروختیم ریختن به حساب ملت | D17: ثبت خودکار یا تأیید ساده | E17: جاری ملت — ۱۲٬۰۰۰٬۰۰۰ | F17: فروش — ۱۲٬۰۰۰٬۰۰۰ | G17: 12000000 | K17: رقم لاتین، بی‌نقطه‌گذاری
A18: R017 | B18: گفتار و تایپ | C18: یه تومن و نیم پول آب دادیم | D18: کارت سؤال، بعد ثبت | E18: قبوض — ۱٬۵۰۰٬۰۰۰ | F18: صندوق — ۱٬۵۰۰٬۰۰۰ | G18: 1500000 | H18: مقیاس مبلغ (۱٬۵۰۰ تومان یا ۱٬۵۰۰٬۰۰۰ تومان؟) از کدام بانک یا صندوق؟ | I18: یک میلیون و پانصد هزار تومان از صندوق | K18: «تومن» محاوره‌ای یعنی میلیون؛ حدس زدن مقیاس و حساب ممنوع است
A19: R018 | B19: گفتار و تایپ | C19: اقای رضایی ۲ میلیون حق زحمه تعمیر کولر رو گرفت، از صندوق دادیم | D19: ثبت خودکار یا تأیید ساده | E19: تعمیر و نگهداری — ۲٬۰۰۰٬۰۰۰ | F19: صندوق — ۲٬۰۰۰٬۰۰۰ | G19: 2000000 | J19: طرف‌حساب: آقای رضایی. | K19: «اقای» بی‌کلاه؛ «حق زحمه» واژهٔ درآمد است ولی پول رفته
A20: R019 | B20: گفتار و تایپ | C20: ۲۵۰ هزار تومن واسه پیک کارت به کارت کردیم از تجارت | D20: ثبت خودکار یا تأیید ساده | E20: حمل‌ونقل — ۲۵۰٬۰۰۰ | F20: جاری تجارت — ۲۵۰٬۰۰۰ | G20: 250000
A21: R020 | B21: گفتار و تایپ | C21: فروختیم ۷ میلیون، نصفش نقد نصفش کارت به ملت | D21: صف حسابدار ← «تحلیل کن» | E21: صندوق — ۳٬۵۰۰٬۰۰۰ جاری ملت — ۳٬۵۰۰٬۰۰۰ | F21: فروش — ۷٬۰۰۰٬۰۰۰ | G21: 7000000 | K21: دو ورود پول در دو حساب؛ یک ردیف ۷ میلیونی در یک حساب غلط است (دو ثبت جدا هم درست است)
A22: R021 | B22: گفتار و تایپ | C22: خانم شاملو ۲ میلیون بابت کاغذ و تونر از صندوق گرفت | D22: ثبت خودکار یا تأیید ساده | E22: ملزومات اداری — ۲٬۰۰۰٬۰۰۰ | F22: صندوق — ۲٬۰۰۰٬۰۰۰ | G22: 2000000 | J22: طرف‌حساب: خانم شاملو. | K22: «شام» درون «شاملو» نباید دستهٔ خوراک بسازد
A23: R022 | B23: گفتار و تایپ | C23: آقای وکیلی ۳ میلیون بابت میز برامون خرید، از ملت بهش دادیم | D23: کارت سؤال، بعد ثبت | E23: سایر هزینه‌ها — ۳٬۰۰۰٬۰۰۰ | F23: جاری ملت — ۳٬۰۰۰٬۰۰۰ | G23: 3000000 | H23: این خرید برای چیست؟ | I23: استفادهٔ بلندمدت | J23: طرف‌حساب: آقای وکیلی. | K23: «وکیل» درون «وکیلی» نباید «پیمانکار» بسازد؛ کالای ماندگار زیر حد ۲۰ میلیون هزینه است، نه دارایی
A24: R023 | B24: گفتار و تایپ | C24: امروز دو میلیون و پونصد خرج غذای مهمونای جلسه شد از صندوق | D24: ثبت خودکار یا تأیید ساده | E24: خوراک — ۲٬۵۰۰٬۰۰۰ | F24: صندوق — ۲٬۵۰۰٬۰۰۰ | G24: 2500000 | K24: «پونصد» محاوره‌ای
A25: R024 | B25: گفتار و تایپ | C25: پول اینترنت دفتر یک و دویست شد، از ملت رفت | D25: ثبت خودکار یا تأیید ساده | E25: قبوض — ۱٬۲۰۰٬۰۰۰ | F25: جاری ملت — ۱٬۲۰۰٬۰۰۰ | G25: 1200000 | K25: «یک و دویست» یعنی ۱٬۲۰۰٬۰۰۰
A26: R025 | B26: بدهی و طلب باز | C26: قبض برق مهر مغازه ۴ میلیون تومان اومده ولی قراره تا آبان پرداختش کنیم. | D26: کارت سؤال، بعد ثبت | E26: قبوض — ۴٬۰۰۰٬۰۰۰ | F26: حساب پرداختنی — اداره برق — ۴٬۰۰۰٬۰۰۰ | G26: 4000000 | H26: طرف حساب چه کسی است؟ | I26: اداره برق | K26: پولی جابه‌جا نشده؛ هیچ ردیف نقدی و هیچ برداشت از صندوق
A27: R026 | B27: بدهی و طلب باز | C27: فاکتور فروش ۲۵ میلیونی برای شرکت آریا تجارت زدیم، قراره آخر ماه بپردازه. | D27: ثبت خودکار یا تأیید ساده | E27: حساب دریافتنی — شرکت آریا تجارت — ۲۵٬۰۰۰٬۰۰۰ | F27: فروش — ۲۵٬۰۰۰٬۰۰۰ | G27: 25000000 | K27: فروش نسیه؛ ورود پول ندارد
A28: R027 | B28: بدهی و طلب باز | C28: از پخش گلستان ۱۸ میلیون جنس گرفتیم، پولش هفتهٔ بعد. | D28: کارت سؤال، بعد ثبت | E28: مواد و کالا — ۱۸٬۰۰۰٬۰۰۰ | F28: حساب پرداختنی — پخش گلستان — ۱۸٬۰۰۰٬۰۰۰ | G28: 18000000 | H28: این خرید برای چیست؟ (اگر پرسید) نام کالا، تعداد و واحد | I28: فروش مجدد ۳۶ کارتن روغن، هر کارتن ۵۰۰ هزار تومان | K28: خرید نسیه؛ «گرفتیم» دریافت پول نیست
A29: R028 | B29: بدهی و طلب باز | C29: تعمیرکار اومد کولر رو درست کرد، ۳ میلیون شد، هنوز بهش ندادیم. | D29: کارت سؤال، بعد ثبت | E29: تعمیر و نگهداری — ۳٬۰۰۰٬۰۰۰ | F29: حساب پرداختنی — آقای رضایی — ۳٬۰۰۰٬۰۰۰ | G29: 3000000 | H29: نام طرف حساب؟ | I29: آقای رضایی | K29: کار انجام‌شده و پرداخت‌نشده = بدهی
A30: R029 | B30: بدهی و طلب باز | C30: حقوق مهر رو هنوز ندادیم؛ ۴۰ میلیون خالص می‌شه. | D30: صف حسابدار ← «تحلیل کن» | E30: حقوق و دستمزد — ۴۰٬۰۰۰٬۰۰۰ | F30: حساب پرداختنی — کارکنان — ۴۰٬۰۰۰٬۰۰۰ | G30: 40000000 | H30: کسور بیمه و مالیات این حقوق چقدر بود؟ | I30: کسوری نداشت | K30: حقوق معوق؛ ردیف نقدی ممنوع؛ «خالص» دوباره پرسیده نشود
A31: R030 | B31: بدهی و طلب باز | C31: خدمات پشتیبانی مهر رو برای مشتری انجام دادیم، ۶ میلیون؛ فاکتورش رفته ولی هنوز پول نداده. | D31: کارت سؤال، بعد ثبت | E31: حساب دریافتنی — شرکت آریا تجارت — ۶٬۰۰۰٬۰۰۰ | F31: خدمات — ۶٬۰۰۰٬۰۰۰ | G31: 6000000 | H31: نام مشتری؟ | I31: شرکت آریا تجارت
A32: R031 | B32: بدهی و طلب باز | C32: قبض گاز ۸۵۰ هزار تومن اومده، پرداخت نشده. | D32: کارت سؤال، بعد ثبت | E32: قبوض — ۸۵۰٬۰۰۰ | F32: حساب پرداختنی — شرکت گاز — ۸۵۰٬۰۰۰ | G32: 850000 | H32: طرف حساب؟ | I32: شرکت گاز
A33: R032 | B33: بدهی و طلب باز | C33: آقای کاظمی ۱۲ میلیون نسیه از ما جنس برد. | D33: ثبت خودکار یا تأیید ساده | E33: حساب دریافتنی — آقای کاظمی — ۱۲٬۰۰۰٬۰۰۰ | F33: فروش — ۱۲٬۰۰۰٬۰۰۰ | G33: 12000000 | K33: «برد» یعنی فروش نسیه؛ ورود پول ندارد
A34: R033 | B34: تسویه | C34: شرکت آریا تجارت ۲۵ میلیون بابت فاکتور فروش قبلی واریز کرد به ملت. | D34: ثبت خودکار یا تأیید ساده | E34: جاری ملت — ۲۵٬۰۰۰٬۰۰۰ | F34: حساب دریافتنی — شرکت آریا تجارت — ۲۵٬۰۰۰٬۰۰۰ | G34: 25000000 | K34: فروش دوباره ثبت نشود
A35: R034 | B35: تسویه | C35: ۱۵ میلیون از ۱۸ میلیون بدهی پخش گلستان رو از تجارت دادیم. | D35: ثبت خودکار یا تأیید ساده | E35: حساب پرداختنی — پخش گلستان — ۱۵٬۰۰۰٬۰۰۰ | F35: جاری تجارت — ۱۵٬۰۰۰٬۰۰۰ | G35: 15000000 | K35: تسویهٔ بخشی؛ ۳ میلیون بدهی باز می‌ماند؛ خرید یا هزینهٔ دوباره ممنوع
A36: R035 | B36: تسویه | C36: قبض برق مهر که اومده بود رو امروز از ملت پرداخت کردیم، ۴ میلیون. | D36: ثبت خودکار یا تأیید ساده | E36: حساب پرداختنی — اداره برق — ۴٬۰۰۰٬۰۰۰ | F36: جاری ملت — ۴٬۰۰۰٬۰۰۰ | G36: 4000000 | K36: هزینهٔ قبوض دوباره ثبت نشود
A37: R036 | B37: تسویه | C37: آقای کاظمی ۵ میلیون از بدهیش رو نقد آورد. | D37: ثبت خودکار یا تأیید ساده | E37: صندوق — ۵٬۰۰۰٬۰۰۰ | F37: حساب دریافتنی — آقای کاظمی — ۵٬۰۰۰٬۰۰۰ | G37: 5000000 | K37: وصول بخشی؛ ماندهٔ ۷ میلیون باز می‌ماند
A38: R037 | B38: تسویه | C38: ۳ میلیون آقای رضایی بابت تعمیر کولر رو از صندوق دادیم. | D38: ثبت خودکار یا تأیید ساده | E38: حساب پرداختنی — آقای رضایی — ۳٬۰۰۰٬۰۰۰ | F38: صندوق — ۳٬۰۰۰٬۰۰۰ | G38: 3000000
A39: R038 | B39: تسویه | C39: ۱۰ میلیون بدهی قبلی به آقای نوری رو تسویه کردیم از ملت. | D39: صف حسابدار ← «تحلیل کن» | E39: — هیچ سندی — | F39: — هیچ سندی — | H39: سند مبنای این بدهی کدام است؟ | I39: ماندهٔ افتتاحیه ثبت نشده؛ سند مبنا نداریم | J39: بدون سند مبنا هیچ سندی ثبت نشود و هزینهٔ حدسی ساخته نشود. فقط اگر ماندهٔ افتتاحیهٔ بدهی به آقای نوری ثبت شود: Dr حساب پرداختنی — آقای نوری / Cr جاری ملت ۱۰٬۰۰۰٬۰۰۰ | K39: تسویهٔ بدهی بی‌مانده؛ هزینه ساختن ممنوع
A40: R039 | B40: شریک و مالک | C40: شریکمون آقای سعیدی ۵۰ میلیون گذاشت تو کار و ریخت به ملت؛ گفت هر وقت لازم شد پسش میدیم. | D40: صف حسابدار ← «تحلیل کن» | E40: جاری ملت — ۵۰٬۰۰۰٬۰۰۰ | F40: جاری شریک — بدهی شرکت — آقای سعیدی — ۵۰٬۰۰۰٬۰۰۰ | G40: 50000000 | K40: «عیدی» درون «سعیدی» حقوق نیست؛ پول شریک درآمد نیست؛ «پسش میدیم» = قرض شریک به شرکت
...

Sheet امتیاز
A1: شاخص | B1: مقدار
A2: کل سناریوها | B2: =COUNTA('تست کور'!$A$2:$A$101)
A3: تست‌شده | B3: =COUNTA('تست کور'!$H$2:$H$101)
A4: درست | B4: =COUNTIF('تست کور'!$H$2:$H$101,"درست")
A5: درست با سؤال‌های درست | B5: =COUNTIF('تست کور'!$H$2:$H$101,"درست با سؤال‌های درست")
A6: امتناع درست | B6: =COUNTIF('تست کور'!$H$2:$H$101,"امتناع درست")
A7: غلط | B7: =COUNTIF('تست کور'!$H$2:$H$101,"غلط")
A8: ثبت اشتباه با اطمینان (آستانه: صفر) | B8: =COUNTIF('تست کور'!$I$2:$I$101,"بله")
A9: نرخ قبولی از تست‌شده‌ها | B9: =IF(B3=0,0,(B4+B5+B6)/B3)
A12: گروه | B12: تعداد | C12: تست‌شده | D12: قبول (درست، با سؤال، امتناع درست) | E12: غلط | F12: ثبت اشتباه با اطمینان | G12: نرخ قبولی
A13: روزانه | B13: =COUNTIF('تست کور'!$B$2:$B$101,A13) | C13: =COUNTIFS('تست کور'!$B$2:$B$101,A13,'تست کور'!$H$2:$H$101,"<>") | D13: =COUNTIFS('تست کور'!$B$2:$B$101,A13,'تست کور'!$H$2:$H$101,"درست")+COUNTIFS('تست کور'!$B$2:$B$101,A13,'تست کور'!$H$2:$H$101,"درست با سؤال‌های درست")+COUNTIFS('تست کور'!$B$2:$B$101,A13,'تست کور'!$H$2:$H$101,"امتناع درست") | E13: =COUNTIFS('تست کور'!$B$2:$B$101,A13,'تست کور'!$H$2:$H$101,"غلط") | F13: =COUNTIFS('تست کور'!$B$2:$B$101,A13,'تست کور'!$I$2:$I$101,"بله") | G13: =IF(C13=0,0,D13/C13)
A14: گفتار و تایپ | B14: =COUNTIF('تست کور'!$B$2:$B$101,A14) | C14: =COUNTIFS('تست کور'!$B$2:$B$101,A14,'تست کور'!$H$2:$H$101,"<>") | D14: =COUNTIFS('تست کور'!$B$2:$B$101,A14,'تست کور'!$H$2:$H$101,"درست")+COUNTIFS('تست کور'!$B$2:$B$101,A14,'تست کور'!$H$2:$H$101,"درست با سؤال‌های درست")+COUNTIFS('تست کور'!$B$2:$B$101,A14,'تست کور'!$H$2:$H$101,"امتناع درست") | E14: =COUNTIFS('تست کور'!$B$2:$B$101,A14,'تست کور'!$H$2:$H$101,"غلط") | F14: =COUNTIFS('تست کور'!$B$2:$B$101,A14,'تست کور'!$I$2:$I$101,"بله") | G14: =IF(C14=0,0,D14/C14)
A15: بدهی و طلب باز | B15: =COUNTIF('تست کور'!$B$2:$B$101,A15) | C15: =COUNTIFS('تست کور'!$B$2:$B$101,A15,'تست کور'!$H$2:$H$101,"<>") | D15: =COUNTIFS('تست کور'!$B$2:$B$101,A15,'تست کور'!$H$2:$H$101,"درست")+COUNTIFS('تست کور'!$B$2:$B$101,A15,'تست کور'!$H$2:$H$101,"درست با سؤال‌های درست")+COUNTIFS('تست کور'!$B$2:$B$101,A15,'تست کور'!$H$2:$H$101,"امتناع درست") | E15: =COUNTIFS('تست کور'!$B$2:$B$101,A15,'تست کور'!$H$2:$H$101,"غلط") | F15: =COUNTIFS('تست کور'!$B$2:$B$101,A15,'تست کور'!$I$2:$I$101,"بله") | G15: =IF(C15=0,0,D15/C15)
A16: تسویه | B16: =COUNTIF('تست کور'!$B$2:$B$101,A16) | C16: =COUNTIFS('تست کور'!$B$2:$B$101,A16,'تست کور'!$H$2:$H$101,"<>") | D16: =COUNTIFS('تست کور'!$B$2:$B$101,A16,'تست کور'!$H$2:$H$101,"درست")+COUNTIFS('تست کور'!$B$2:$B$101,A16,'تست کور'!$H$2:$H$101,"درست با سؤال‌های درست")+COUNTIFS('تست کور'!$B$2:$B$101,A16,'تست کور'!$H$2:$H$101,"امتناع درست") | E16: =COUNTIFS('تست کور'!$B$2:$B$101,A16,'تست کور'!$H$2:$H$101,"غلط") | F16: =COUNTIFS('تست کور'!$B$2:$B$101,A16,'تست کور'!$I$2:$I$101,"بله") | G16: =IF(C16=0,0,D16/C16)
A17: شریک و مالک | B17: =COUNTIF('تست کور'!$B$2:$B$101,A17) | C17: =COUNTIFS('تست کور'!$B$2:$B$101,A17,'تست کور'!$H$2:$H$101,"<>") | D17: =COUNTIFS('تست کور'!$B$2:$B$101,A17,'تست کور'!$H$2:$H$101,"درست")+COUNTIFS('تست کور'!$B$2:$B$101,A17,'تست کور'!$H$2:$H$101,"درست با سؤال‌های درست")+COUNTIFS('تست کور'!$B$2:$B$101,A17,'تست کور'!$H$2:$H$101,"امتناع درست") | E17: =COUNTIFS('تست کور'!$B$2:$B$101,A17,'تست کور'!$H$2:$H$101,"غلط") | F17: =COUNTIFS('تست کور'!$B$2:$B$101,A17,'تست کور'!$I$2:$I$101,"بله") | G17: =IF(C17=0,0,D17/C17)
A18: دارایی ثابت و تعمیر | B18: =COUNTIF('تست کور'!$B$2:$B$101,A18) | C18: =COUNTIFS('تست کور'!$B$2:$B$101,A18,'تست کور'!$H$2:$H$101,"<>") | D18: =COUNTIFS('تست کور'!$B$2:$B$101,A18,'تست کور'!$H$2:$H$101,"درست")+COUNTIFS('تست کور'!$B$2:$B$101,A18,'تست کور'!$H$2:$H$101,"درست با سؤال‌های درست")+COUNTIFS('تست کور'!$B$2:$B$101,A18,'تست کور'!$H$2:$H$101,"امتناع درست") | E18: =COUNTIFS('تست کور'!$B$2:$B$101,A18,'تست کور'!$H$2:$H$101,"غلط") | F18: =COUNTIFS('تست کور'!$B$2:$B$101,A18,'تست کور'!$I$2:$I$101,"بله") | G18: =IF(C18=0,0,D18/C18)
A19: پیش‌پرداخت، پیش‌دریافت، ودیعه | B19: =COUNTIF('تست کور'!$B$2:$B$101,A19) | C19: =COUNTIFS('تست کور'!$B$2:$B$101,A19,'تست کور'!$H$2:$H$101,"<>") | D19: =COUNTIFS('تست کور'!$B$2:$B$101,A19,'تست کور'!$H$2:$H$101,"درست")+COUNTIFS('تست کور'!$B$2:$B$101,A19,'تست کور'!$H$2:$H$101,"درست با سؤال‌های درست")+COUNTIFS('تست کور'!$B$2:$B$101,A19,'تست کور'!$H$2:$H$101,"امتناع درست") | E19: =COUNTIFS('تست کور'!$B$2:$B$101,A19,'تست کور'!$H$2:$H$101,"غلط") | F19: =COUNTIFS('تست کور'!$B$2:$B$101,A19,'تست کور'!$I$2:$I$101,"بله") | G19: =IF(C19=0,0,D19/C19)
A20: حقوق و کارکنان | B20: =COUNTIF('تست کور'!$B$2:$B$101,A20) | C20: =COUNTIFS('تست کور'!$B$2:$B$101,A20,'تست کور'!$H$2:$H$101,"<>") | D20: =COUNTIFS('تست کور'!$B$2:$B$101,A20,'تست کور'!$H$2:$H$101,"درست")+COUNTIFS('تست کور'!$B$2:$B$101,A20,'تست کور'!$H$2:$H$101,"درست با سؤال‌های درست")+COUNTIFS('تست کور'!$B$2:$B$101,A20,'تست کور'!$H$2:$H$101,"امتناع درست") | E20: =COUNTIFS('تست کور'!$B$2:$B$101,A20,'تست کور'!$H$2:$H$101,"غلط") | F20: =COUNTIFS('تست کور'!$B$2:$B$101,A20,'تست کور'!$I$2:$I$101,"بله") | G20: =IF(C20=0,0,D20/C20)
A21: ارزش افزوده | B21: =COUNTIF('تست کور'!$B$2:$B$101,A21) | C21: =COUNTIFS('تست کور'!$B$2:$B$101,A21,'تست کور'!$H$2:$H$101,"<>") | D21: =COUNTIFS('تست کور'!$B$2:$B$101,A21,'تست کور'!$H$2:$H$101,"درست")+COUNTIFS('تست کور'!$B$2:$B$101,A21,'تست کور'!$H$2:$H$101,"درست با سؤال‌های درست")+COUNTIFS('تست کور'!$B$2:$B$101,A21,'تست کور'!$H$2:$H$101,"امتناع درست") | E21: =COUNTIFS('تست کور'!$B$2:$B$101,A21,'تست کور'!$H$2:$H$101,"غلط") | F21: =COUNTIFS('تست کور'!$B$2:$B$101,A21,'تست کور'!$I$2:$I$101,"بله") | G21: =IF(C21=0,0,D21/C21)
A22: چک | B22: =COUNTIF('تست کور'!$B$2:$B$101,A22) | C22: =COUNTIFS('تست کور'!$B$2:$B$101,A22,'تست کور'!$H$2:$H$101,"<>") | D22: =COUNTIFS('تست کور'!$B$2:$B$101,A22,'تست کور'!$H$2:$H$101,"درست")+COUNTIFS('تست کور'!$B$2:$B$101,A22,'تست کور'!$H$2:$H$101,"درست با سؤال‌های درست")+COUNTIFS('تست کور'!$B$2:$B$101,A22,'تست کور'!$H$2:$H$101,"امتناع درست") | E22: =COUNTIFS('تست کور'!$B$2:$B$101,A22,'تست کور'!$H$2:$H$101,"غلط") | F22: =COUNTIFS('تست کور'!$B$2:$B$101,A22,'تست کور'!$I$2:$I$101,"بله") | G22: =IF(C22=0,0,D22/C22)
A23: وام | B23: =COUNTIF('تست کور'!$B$2:$B$101,A23) | C23: =COUNTIFS('تست کور'!$B$2:$B$101,A23,'تست کور'!$H$2:$H$101,"<>") | D23: =COUNTIFS('تست کور'!$B$2:$B$101,A23,'تست کور'!$H$2:$H$101,"درست")+COUNTIFS('تست کور'!$B$2:$B$101,A23,'تست کور'!$H$2:$H$101,"درست با سؤال‌های درست")+COUNTIFS('تست کور'!$B$2:$B$101,A23,'تست کور'!$H$2:$H$101,"امتناع درست") | E23: =COUNTIFS('تست کور'!$B$2:$B$101,A23,'تست کور'!$H$2:$H$101,"غلط") | F23: =COUNTIFS('تست کور'!$B$2:$B$101,A23,'تست کور'!$I$2:$I$101,"بله") | G23: =IF(C23=0,0,D23/C23)
A24: برگشت | B24: =COUNTIF('تست کور'!$B$2:$B$101,A24) | C24: =COUNTIFS('تست کور'!$B$2:$B$101,A24,'تست کور'!$H$2:$H$101,"<>") | D24: =COUNTIFS('تست کور'!$B$2:$B$101,A24,'تست کور'!$H$2:$H$101,"درست")+COUNTIFS('تست کور'!$B$2:$B$101,A24,'تست کور'!$H$2:$H$101,"درست با سؤال‌های درست")+COUNTIFS('تست کور'!$B$2:$B$101,A24,'تست کور'!$H$2:$H$101,"امتناع درست") | E24: =COUNTIFS('تست کور'!$B$2:$B$101,A24,'تست کور'!$H$2:$H$101,"غلط") | F24: =COUNTIFS('تست کور'!$B$2:$B$101,A24,'تست کور'!$I$2:$I$101,"بله") | G24: =IF(C24=0,0,D24/C24)
... A27: نباید ثبت شود | B27: =COUNTIF('تست کور'!$B$2:$B$101,A27) | C27: =COUNTIFS('تست کور'!$B$2:$B$101,A27,'تست کور'!$H$2:$H$101,"<>") | D27: =COUNTIFS('تست کور'!$B$2:$B$101,A27,'تست کور'!$H$2:$H$101,"درست")+COUNTIFS('تست کور'!$B$2:$B$101,A27,'تست کور'!$H$2:$H$101,"درست با سؤال‌های درست")+COUNTIFS('تست کور'!$B$2:$B$101,A27,'تست کور'!$H$2:$H$101,"امتناع درست") | E27: =COUNTIFS('تست کور'!$B$2:$B$101,A27,'تست کور'!$H$2:$H$101,"غلط") | F27: =COUNTIFS('تست کور'!$B$2:$B$101,A27,'تست کور'!$I$2:$I$101,"بله") | G27: =IF(C27=0,0,D27/C27)

Sheet راهنمای آزمون
A1: موضوع | B1: ۱۰۰ تراکنش برای آزمون حالت AI روشن و «تحلیل کن» صف بررسی
A2: واحد مبلغ | B2: همهٔ مبالغ به تومان
A3: نسخه | B3: 1405-07-29
A5: پیش از شروع
A6: ۱. | B6: دفتر تازهٔ کسب‌وکار، تجربهٔ حرفه‌ای، کدینگ پیشنهادی نصب‌شده، حالت فهم با AI روشن.
A7: ۲. | B7: حساب‌ها: صندوق با افتتاحیهٔ ۱۰۰٬۰۰۰٬۰۰۰؛ جاری ملت ۵۰۰٬۰۰۰٬۰۰۰؛ جاری تجارت ۲۰۰٬۰۰۰٬۰۰۰؛ تنخواه رضا احمدی با ماندهٔ صفر.
A8: ۳. | B8: حد سرمایه‌ای شدن دارایی: ۲۰٬۰۰۰٬۰۰۰ تومان (از تنظیمات قانون ثبت خودکار).
A9: ۴. | B9: ارزش افزوده: دفتر مشمول، نرخ ۱۰٪.
A10: ۵. | B10: موارد را به ترتیب کد وارد کن؛ هر مورد «وابسته به» فقط بعد از پیش‌نیازش معنا دارد.
A11: ۶. | B11: جواب سؤال‌ها را دقیقاً از ستون «جواب‌هایی که بده» بده؛ چیزی اضافه نگو.
A13: مسیرها
A14: ثبت خودکار یا تأیید ساده | B14: سیستم خودش سند درست را می‌سازد یا فقط تأیید می‌خواهد.
A15: کارت سؤال، بعد ثبت | B15: یک یا چند کارت سؤال می‌آید؛ جواب ستون «جواب‌هایی که بده» را بده، بعد سند باید با کلید یکی باشد.
A16: صف حسابدار ← «تحلیل کن» | B16: مورد به صف حسابدار می‌رود؛ «تحلیل کن» را بزن، سؤال‌ها را جواب بده و سند را با کلید مقایسه کن.
A17: امتناع درست — شکاف شناخته‌شدهٔ سیستم | B17: ثبت درست در کلید آمده، ولی سیستم فعلی این شکل را هنوز ثبت نمی‌کند؛ پیام صریح «هنوز پشتیبانی نمی‌شود» و نبودِ سند غلط یعنی «امتناع درست».
A18: نباید هیچ سندی ثبت شود | B18: هیچ سندی نباید ساخته شود؛ هر سندی «غلط» است.
A20: نتیجه‌گذاری
A21: درست | B21: مسیر و سند (حساب‌ها، مبلغ‌ها، طرف‌حساب، نبودِ ردیف نقدی وقتی پولی جابه‌جا نشده) با کلید یکی است، بی سؤال اضافه.
A22: درست با سؤال‌های درست | B22: سند درست است و فقط سؤال‌هایی پرسیده شد که واقعاً از متن درنمی‌آمد.
A23: امتناع درست | B23: سیستم ثبت نکرد و دلیلش درست بود (شکاف شناخته‌شده، نبودِ سند مبنا، «نباید ثبت شود»).
A24: غلط | B24: هر سند دیگر، سؤال دربارهٔ چیزی که متن گفته بود، یا ثبت چیزی که نباید ثبت می‌شد.
A25: ثبت اشتباه با اطمینان | B25: «بله» یعنی سند غلط بی هیچ سؤال یا هشداری ثبت شد. آستانهٔ قبولش صفر است و مهم‌ترین عدد این آزمون است.
A27: خانه‌های پرکردنی | B27: فقط خانه‌های زرد برگهٔ «تست کور» را پر کن. برگهٔ «امتیاز» خودش حساب می‌شود.
A28: نمونهٔ پرشده | B28: R003 · خروجی: «Dr قبوض ۱٬۲۰۰٬۰۰۰ / Cr جاری ملت ۱٬۲۰۰٬۰۰۰، بی سؤال» · نتیجه: درست · ثبت اشتباه با اطمینان: خیر
