Workbook

Sheet تست کور
A1: کد سناریو | B1: سرفصل حسابداری (دسته) | C1: سطح دشواری | D1: متن سناریوی صوتی (Voice Transcript) | E1: نوع سناریو | F1: عمدی مبهم؟ | G1: رفتار مورد انتظار سیستم | H1: خروجی / پاسخ ثبت‌شده حساب‌یار | I1: نتیجه ارزیابی حساب‌یار | J1: نوع خطای شناسایی‌شده | K1: توضیحات و یادداشت تستر | L1: در دامنهٔ فاز فعلی؟ | M1: ثبت اشتباه با اطمینان؟
A2: T001 | B2: ۱. پیش‌پرداخت، هزینه و دوره مالی | C2: آسان | D2: سلام حساب‌یار جان، امروز صب دوازده میلیون تومن از حساب سامان ریختم به حساب آقای اسدی بابت اجاره اردیبهشت ماه دفتر مرکزی، سندشو بزن. | E2: تک‌رویدادی | F2: خیر | G2: ثبت سند دوبل قطعی (هزینه اجاره / بانک سامان) | L2: تا حدی — پیش‌پرداخت قاعده دارد
A3: T002 | B3: ۱. پیش‌پرداخت، هزینه و دوره مالی | C3: متوسط | D3: حساب‌یار، پنجاه میلیون زدم به حساب بیمه ایران واسه کل بیمه مسئولیت مدنی یک‌ساله شرکت، از اول فروردین تا آخر اسفند همین امسال. | E3: تک‌رویدادی | F3: خیر | G3: ثبت پیش‌پرداخت بیمه به عنوان دارایی جاری و مستهلک‌سازی ماهانه | L3: تا حدی — پیش‌پرداخت قاعده دارد
A4: T003 | B4: ۱. پیش‌پرداخت، هزینه و دوره مالی | C4: سخت | D4: بیست میلیون دادم به موجر دفتر، ده تومنش مال کرایه عقب‌افتاده اسفند پارساله، ده تومنم علی‌الحساب مال فروردین و اردیبهشت امسال، از حساب ملی دادم. | E4: چندرویدادی مرکب | F4: خیر | G4: تفکیک بدهی سنواتی گذشته از پیش‌پرداخت اجاره دوره جاری | L4: تا حدی — پیش‌پرداخت قاعده دارد
A5: T004 | B5: ۱. پیش‌پرداخت، هزینه و دوره مالی | C5: چالش‌برانگیز | D5: یه سی تومن ریختم واسه چاپخونه ولی نمیدونم کاتالوگ شرکتو قراره بعد عید بیاره یا فاکتورشو باطل کرده، فعلا تو حسابت باشه تا بعد! | E5: ابهام نیازمند سؤال | F5: بله | G5: طرح سؤال تکمیلی شفاف‌سازی و ثبت در پیش‌پرداخت نامشخص | L5: تا حدی — پیش‌پرداخت قاعده دارد
A6: T005 | B6: ۱. پیش‌پرداخت، هزینه و دوره مالی | C6: متوسط | D6: هزینه پذیرایی جلسه هیئت مدیره شد سه میلیون و چهارصد، آقای حسینی از جیب خودش کارت کشیده، طلبکارش کنین لطفا. | E6: تک‌رویدادی | F6: خیر | G6: ثبت هزینه پذیرایی و اداری به بستانکاری جاری شرکا / آقای حسینی | L6: تا حدی — پیش‌پرداخت قاعده دارد
A7: T006 | B7: ۱. پیش‌پرداخت، هزینه و دوره مالی | C7: سخت | D7: صد و بیست میلیون پیش‌پیش ریختیم حساب کارخونه فولاد مبارکه واسه خرید ورق، هنوز هیچی فاکتور نکرده و بار نرسیده. | E7: تک‌رویدادی | F7: خیر | G7: ثبت پیش‌پرداخت خرید کالا تجاری / بانک (نه هزینه خرید کالا) | L7: تا حدی — پیش‌پرداخت قاعده دارد
A8: T007 | B8: ۱. پیش‌پرداخت، هزینه و دوره مالی | C8: چالش‌برانگیز | D8: یه پنج تومن دادم به نظافتچی راهروها، رسیدم نگرفتم، فاکتورم که ندارن، همینو یه جوری ثبت کن تو سیستم بره پی کارش. | E8: ابهام نیازمند سؤال | F8: بله | G8: هشدار نبود مدارک مثبته و تفکیک هزینه قانونی از غیرقابل‌قبول مالیاتی | L8: تا حدی — پیش‌پرداخت قاعده دارد
A9: T008 | B9: ۱. پیش‌پرداخت، هزینه و دوره مالی | C9: متوسط | D9: قبض برق و گاز کارگاه اومده روی هم نه میلیون تومن، موعد پرداختش هفته بعده ولی الان فاکتورش اومده، چیکارش کنیم؟ | E9: تک‌رویدادی | F9: خیر | G9: شناسایی بدهی جاری و هزینه قبوض بر مبنای تعهدی (پیش از پرداخت) | L9: تا حدی — پیش‌پرداخت قاعده دارد
A10: T009 | B10: ۱. پیش‌پرداخت، هزینه و دوره مالی | C10: سخت | D10: پونزده میلیون شارژ ساختمان اداری رو برای شش ماه جلوتر با چک نقدی تسویه کردم، چک هم پاس شد. | E10: تک‌رویدادی | F10: خیر | G10: تفکیک هزینه جاری دوره از پیش‌پرداخت ماه‌های آتی شارژ اداری | L10: تا حدی — پیش‌پرداخت قاعده دارد
A11: T010 | B11: ۱. پیش‌پرداخت، هزینه و دوره مالی | C11: چالش‌برانگیز | D11: امروز هفت میلیون هزینه کردیم، بعدا بهت میگم چی بود فقط تو سیستم تراز بخوره به هم نریزه! | E11: ابهام غیرقابل ثبت | F11: بله | G11: رد قطعی ثبت سند به علت فقدان سررفصل، طرف حساب و مدرک مالی | L11: تا حدی — پیش‌پرداخت قاعده دارد
A12: T011 | B12: ۲. دارایی ثابت، استهلاک و مخارج سرمایه‌ای | C12: متوسط | D12: یه دستگاه لپ‌تاپ ایسوس خریدیم واسه گرافیست شرکت به مبلغ چهل و هشت میلیون تومن، نقدی از حساب تجارت پرداخت شد. | E12: تک‌رویدادی | F12: خیر | G12: ثبت دارایی ثابت مشهود (اثاثه و تجهیزات رایانه‌ای) و کاهش بانک | L12: خیر — قاعده‌اش ساخته نشده
A13: T012 | B13: ۲. دارایی ثابت، استهلاک و مخارج سرمایه‌ای | C13: سخت | D13: سیصد و پنجاه میلیون تومن دادیم خط تولید کارگاه رو اساسی اورهال کردن، قطعات موتور عوض شد و ظرفیت تولید دو برابر شد. | E13: تک‌رویدادی | F13: خیر | G13: ثبت مخارج سرمایه‌ای و افزایش ارزش دفتری ماشین‌آلات (نه هزینه جاری) | L13: خیر — قاعده‌اش ساخته نشده
... A121: T120 | B121: ۱۲. درآمد غیرعملیاتی، ضایعات و رویداد غیرعادی | C121: چالش‌برانگیز | D121: یه مبلغ مشکوک پنجاه میلیون تومانی بدون مشخصات به حساب اومده، مدیر میگه بزن به حساب درآمدهای متفرقه کسی نفهمه! | E121: ابهام غیرقابل ثبت | F121: بله | G121: رد ثبت درآمد متفرقه بدون منشأ، ثبت واریزی نامشخص و اعلام خطرات پولشویی و ممیزی | L121: خیر — قاعده‌اش ساخته نشده

Sheet کلید پاسخ کامل
A1: کد سناریو | B1: سرفصل حسابداری (دسته) | C1: عنوان و ماهیت رویداد مالی | D1: حساب(های) بدهکار استاندارد | E1: حساب(های) بستانکار استاندارد | F1: مبلغ مبنا (تومان) | G1: طرف‌حساب / اشخاص مرتبط | H1: تاریخ / سررسید / دوره | I1: رفتار استاندارد هوش مصنوعی در ابهام یا ترکیب | J1: مرجع استاندارد حسابداری / قانون مالیاتی
A2: T001 | B2: ۱. پیش‌پرداخت، هزینه و دوره مالی | C2: پرداخت نقدی اجاره اردیبهشت دفتر مرکزی | D2: هزینه اجاره اماکن اداری | E2: موجودی بانک سامان | F2: 12000000 | G2: آقای اسدی (موجر) | H2: اردیبهشت ماه جاری | I2: ثبت قطعی بدون ابهام با تاریخ روز و مرکز هزینه اداری | J2: استاندارد حسابداری ۱ و ۳ (تداوم و تطابق)
A3: T002 | B3: ۱. پیش‌پرداخت، هزینه و دوره مالی | C3: پیش‌پرداخت بیمه مسئولیت مدنی سالانه | D3: پیش‌پرداخت بیمه (دارایی جاری) | E3: موجودی بانک / اسناد پرداختنی | F3: 50000000 | G3: شرکت سهامی بیمه ایران | H3: ۱ فروردین تا ۲۹ اسفند (یک‌ساله) | I3: شناسایی اولیه در دارایی جاری و زمان‌بندی استهلاک ۱۲ ماهه | J3: ماده ۱۴۸ قانون مالیات‌های مستقیم و استانداردهای مالی
A4: T003 | B4: ۱. پیش‌پرداخت، هزینه و دوره مالی | C4: پرداخت ترکیبی بدهی سنواتی و پیش‌پرداخت جاری | D4: حساب‌های پرداختنی (۱۰ م) + پیش‌پرداخت اجاره (۱۰ م) | E4: موجودی بانک ملی | F4: 20000000 | G4: موجر دفتر مرکـزی | H4: اسفند سال قبل و بهار سال جاری | I4: تفکیک خودکار مبلغ به دو آرتیکل: تسویه بدهی و پیش‌پرداخت | J4: اصل تطابق هزینه با درآمد و استانداردهای تفکیک دوره
A5: T004 | B5: ۱. پیش‌پرداخت، هزینه و دوره مالی | C5: واریز وجه نامشخص به چاپخانه بدون فاکتور قطعی | D5: پیش‌پرداخت سفارشات چاپی / علی‌الحساب | E5: موجودی بانک | F5: 30000000 | G5: چاپخانه طرف قرارداد | H5: نامشخص (نیاز به پیگیری) | I5: توقف ثبت هزینه قطعی؛ طرح سؤال: آیا سفارش چاپ نهایی شده یا خیر؟ | J5: آیین‌نامه تحریر دفاتر و الزامات صدور مدارک مثبته
A6: T005 | B6: ۱. پیش‌پرداخت، هزینه و دوره مالی | C6: پرداخت هزینه پذیرایی هیئت مدیره از جیب سهامدار | D6: هزینه پذیرایی، رفاهی و جلسات اداری | E6: جاری شرکا و سهامداران (آقای حسینی) | F6: 3400000 | G6: آقای حسینی (عضو هیئت مدیره) | H6: روز جاری | I6: شناسایی هزینه جاری و افزایش بستانکاری سهامدار بدون دخالت بانک | J6: قانون تجارت و ماده ۱۲۹ و استانداردهای افشای اشخاص وابسته
A7: T006 | B7: ۱. پیش‌پرداخت، هزینه و دوره مالی | C7: پیش‌پرداخت خرید مواد اولیه از بورس/کارخانه | D7: پیش‌پرداخت خرید کالا و مواد اولیه | E7: موجودی بانک | F7: 120000000 | G7: کارخانه فولاد مبارکه اصفهان | H7: تحویل در دوره آتی | I7: جلوگیری از ثبت مستقیم در حساب خرید یا موجودی تا زمان تحویل کالا | J7: استاندارد حسابداری ۸ (حسابداری موجودی مواد و کالا)
A8: T007 | B8: ۱. پیش‌پرداخت، هزینه و دوره مالی | C8: پرداخت وجه نظافتچی بدون رسید و کد ملی | D8: هزینه‌های عمومی و اداری (خدمات نظافت) | E8: موجودی صندوق / بانک | F8: 5000000 | G8: نظافتچی متفرقه (فاقد مشخصات) | H8: روز جاری | I8: هشدار به کاربر: هزینه فاقد فاکتور معتبر جزء هزینه‌های غیرقابل قبول مالیاتی است | J8: ماده ۱۴۷ و ۱۴۸ قانون مالیات‌های مستقیم
A9: T008 | B9: ۱. پیش‌پرداخت، هزینه و دوره مالی | C9: دریافت قبض خدمات عمومی (آب/برق/گاز) پیش از سررسید | D9: هزینه آب، برق، گاز و انرژی کارگاه | E9: سایر حساب‌ها و اسناد پرداختنی جاری | F9: 9000000 | G9: شرکت توزیع نیروی برق / شرکت گاز | H9: سررسید هفته آتی | I9: ثبت تعهدی بدهی پیش از خروج نقدینگی و تعیین موعد پرداخت سررسید | J9: مبنای تعهدی استانداردهای حسابداری دولتی و بخش خصوصی
A10: T009 | B10: ۱. پیش‌پرداخت، هزینه و دوره مالی | C10: شارژ شش‌ماهه پیشاپیش ساختمان اداری | D10: هزینه شارژ جاری (۲.۵ م) + پیش‌پرداخت شارژ (۱۲.۵ م) | E10: موجودی بانک / اسناد پرداختنی | F10: 15000000 | G10: مدیریت ساختمان برج اداری | H10: شش ماهه آینده | I10: تفکیک سهم ماه جاری از سهم پنج ماه آینده در دو سرفصل مجزا | J10: اصل تطابق هزینه‌ها با درآمدهای دوره مالی
A11: T010 | B11: ۱. پیش‌پرداخت، هزینه و دوره مالی | C11: دستور پرداخت بدون ذکر سرفصل و مستندات | D11: نامشخص (عدم امکان صدور سند) | E11: نامشخص | F11: 7000000 | G11: نامشخص | H11: نامشخص | I11: رد قاطع ثبت حسابداری و طرح پیام: لطفاً نوع هزینه و طرف‌حساب را مشخص فرمایید | J11: قانون پایانه‌های فروشگاهی و استانداردهای اسناد حسابداری
A12: T011 | B12: ۲. دارایی ثابت، استهلاک و مخارج سرمایه‌ای | C12: خرید رایانه و لپ‌تاپ جهت واحد طراحی | D12: دارایی ثابت مشهود - تجهیزات و ماشین‌آلات اداری | E12: موجودی بانک تجارت | F12: 48000000 | G12: فروشگاه رایانه / شرکت پارس | H12: روز جاری | I12: ثبت در سرفصل دارایی ثابت و صدور پلاک اموال و شروع استهلاک از ماه بعد | J12: استاندارد حسابداری ۱۱ (دارایی‌های ثابت مشهود)
A13: T012 | B13: ۲. دارایی ثابت، استهلاک و مخارج سرمایه‌ای | C13: تعمیر اساسی و افزایش ظرفیت خط تولید | D13: دارایی ثابت مشهود - ماشین‌آلات کارخانه | E13: موجودی بانک / حساب‌های پرداختنی | F13: 350000000 | G13: پیمانکار فنی و مهندسی ماشین‌آلات | H13: دوره جاری | I13: سرمایه‌ای منظور کردن مخارج (افزایش ارزش دفتری و تجدید عمر مفید) | J13: استاندارد حسابداری ۱۱ (مخارج بعدی دارایی‌های ثابت)
... A40: T039 | B40: ۴. دریافتنی و پرداختنی تجاری | C40: تسویه غیرنقدی طلبکار از طریق تحویل کالا | D40: حساب‌های پرداختنی تجاری (آقای رادمنش) | E40: درآمد فروش کالا (یا موجودی کالا) | F40: 10000000 | G40: آقای رادمنش (طلبکار تجاری) | H40: روز جاری | I40: صدور فاکتور رسمی فروش و بستن حساب بدهی بدون رد و بدل وجه نقد | J40: قانون پایانه‌های فروشگاهی و استانداردهای معاوضه دارایی
A41: T040 | B41: ۴. دریافتنی و پرداختنی تجاری | C41: مغایرت بازرگانی مستمر و درخواست سند تسویه صوری | D41: نامشخص (عدم امکان صدور سند تعدیل) | E41: نامشخص | F41: نامشخص | G41: برادران کمالی (مشتری/تامین‌کننده) | H41: نامشخص | I41: رد قاطع ثبت دستوری و صدور هشدار تهیه صورت مغایرت حساب اشخاص | J41: آیین‌نامه تحریر دفاتر قانونی و استانداردهای کنترل حساب‌ها
A42: T041 | B42: ۵. چک و سفته و اسناد تجاری | C42: دریافت چک صیادی موعددار بابت تسویه فاکتور فروش | D42: اسناد دریافتنی تجاری نزد صندوق | E42: حساب‌های دریافتنی تجاری (مشتری) | F42: 65000000 | G42: مشتری صادرکننده چک | H42: سررسید ۱۵ ماه بعد | I42: ثبت مشخصات شناسه صیاد، شماره چک، تاریخ سررسید و بانک صادرکننده | J42: قانون جدید صدور چک و سامانه صیاد بانک مرکزی
A43: T042 | B43: ۵. چک و سفته و اسناد تجاری | C43: نکول و برگشت چک دریافتنی مشتری در سررسید | D43: اسناد دریافتنی واخواست‌شده و برگشتی | E43: اسناد دریافتنی در جریان وصول (بانک) | F43: 65000000 | G43: صاحب چک برگشتی | H43: سررسید روز جاری | I43: خروج از حساب اسناد در جریان وصول و انتقال به مطالبات حقوقی و برگشتی | J43: قانون تجارت (مواد ۲۴۵ به بعد) و استانداردهای اسناد تجاری
A44: T043 | B44: ۵. چک و سفته و اسناد تجاری | C44: پاس شدن چک شرکت به همراه کسر کارمزد بانکی | D44: اسناد پرداختنی (۵۰ م) + هزینه کارمزد بانکی (۵۰ هـ) | E44: موجودی حساب جاری بانک | F44: 50050000 | G44: دارنده چک و بانک عامل | H44: سررسید روز جاری | I44: تفکیک بدهی اسناد تجاری از کارمزد تراکنش خدمات بانکی | J44: استاندارد بدهی‌های مالی و استانداردهای هزینه خدمات بانکی
A45: T044 | B45: ۵. چک و سفته و اسناد تجاری | C45: صدور چک تضمین بدون مبلغ و تاریخ به پیمانکار | D45: حساب‌های انتظامی - چک‌های تضمینی صادره | E45: طرف حساب‌های انتظامی - تعهدات چک‌های تضمینی | F45: 100000000 | G45: آهنگر و پیمانکار قرارداد | H45: نامشخص (تضمینی) | I45: رد ثبت به عنوان اسناد پرداختنی تجاری و ثبت انحصاری در حساب‌های انتظامی | J45: استانداردهای بین‌المللی و داخلی تعهدات بالقوه و تضمین‌ها
A46: T045 | B46: ۵. چک و سفته و اسناد تجاری | C46: ظهرنویسی و خرج کردن چک مشتری جهت تسویه بدهی | D46: حساب‌های پرداختنی تجاری (آقای کبیری) | E46: اسناد دریافتنی تجاری (چک آقای مرادی) | F46: 80000000 | G46: آقای کبیری (طلبکار) و مرادی (صادرکننده) | H46: سررسید چک موصوف | I46: ثبت انتقال تعهد و انتقال ریسک نکول چک به طرفیت شخص ثالث در یادداشت‌ها | J46: قانون تجارت در خصوص ظهرنویسی و واگذاری برات و چک
A47: T046 | B47: ۵. چک و سفته و اسناد تجاری | C47: استرداد سفته تضمین حسن اجرای قرارداد اداره گاز | D47: طرف حساب انتظامی - تعهدات سفته‌های وثیقه | E47: حساب‌های انتظامی - سفته‌های ضمانتی نزد دیگران | F47: نامشخص | G47: اداره گاز استان | H47: خاتمه قرارداد | I47: بستن معکوس ردیف حساب‌های انتظامی پس از اخذ لاشه اسناد سفته | J47: دستورالعمل تضمین معاملات دولتی و استانداردهای وثایق
A48: T047 | B48: ۵. چک و سفته و اسناد تجاری | C48: وصول بخشی از وجه چک و اخذ گواهی عدم پرداخت مانده | D48: بانک (۴۰ م) + اسناد دریافتنی نکول‌شده (۳۰ م) | E48: اسناد دریافتنی در جریان وصول (۷۰ م) | F48: 70000000 | G48: مشتری و صادرکننده چک | H48: روز جاری | I48: تفکیک مبلغ نقدی وصولی در بانک از باقیمانده نکول‌شده و ارجاع به پیگیری حقوقی | J48: ماده ۵ مکرر قانون اصلاح قانون صدور چک
A49: T048 | B49: ۵. چک و سفته و اسناد تجاری | C49: تنزیل چک دریافتنی مدت‌دار نزد بازار آزاد/صرافی | D49: موجودی نقد/بانک (۸۳ م) + هزینه مالی تنزیل (۷ م) | E49: اسناد دریافتنی تجاری (۹۰ م) | F49: 90000000 | G49: صراف / خریدار دین چک | H49: سررسید چک واگذارشده | I49: تفکیک عایدی خالص نقد از هزینه کارمزد تنزیل با هشدار تعهد احتمالی ضامن | J49: استاندارد ابزارهای مالی و مقررات ربا و سود تنزیل اسناد تجاری
A50: T049 | B50: ۵. چک و سفته و اسناد تجاری | C50: دریافت دسته چک جدید و پرداخت کارمزد صدور بانک | D50: هزینه خدمات و کارمزد بانکی | E50: موجودی حساب بانک تجارت | F50: 200000 | G50: بانک تجارت شعبه مرکزی | H50: روز جاری | I50: ثبت هزینه کارمزد در سود و زیان و معرفی شماره سریال چک‌ها در خزانه سیستم | J50: مقررات بانکداری و قانون چک صیادی
A51: T050 | B51: ۵. چک و سفته و اسناد تجاری | C51: واگذاری چک امانی/دست‌لاف به شریک کاری | D51: اسناد انتظامی - چک‌های نزد امانت شریک | E51: طرف حساب انتظامی - تعهدات امانی چک | F51: 50000000 | G51: شریک تجاری (آقای ... ) | H51: کوتاه‌مدت امانی | I51: طرح سؤال: هدف چک چیست؟ اگر امانی است صرفاً در انتظامی ثبت شود نه تجاری | J51: قانون مدنی در باب عقد ودیعه و امانت‌داری مالی
A52: T051 | B52: ۶. وام و تسهیلات بانکی | C52: واریز اصل تسهیلات بانکی طرح توسعه به حساب شرکت | D52: موجودی حساب بانک تجارت | E52: تسهیلات مالی دریافتی بلندمدت بانکی | F52: 500000000 | G52: بانک تجارت (شعبه تسهیلات‌دهنده) | H52: بازپرداخت ۳۶ ماهه | I52: ثبت اصل مبلغ تسهیلات و ایجاد جدول زمان‌بندی اقساط و بهره آتی | J52: استاندارد حسابداری ۱۶ (هزینه‌های تامین مالی)
A53: T052 | B53: ۶. وام و تسهیلات بانکی | C53: پرداخت قسط وام بانکی مرکب از اصل و سود بانکی | D53: تسهیلات بانکی (۱۷ م) + هزینه مالی بهره وام (۶ م) | E53: موجودی حساب بانک ملت | F53: 23000000 | G53: بانک ملت | H53: سررسید قسط ماهانه | I53: تفکیک دقیق کاهش اصل بدهی از هزینه مالی دوره جاری طبق جدول استهلاک وام | J53: استاندارد حسابداری ۱۶ و ماده ۱۴۸ ق.م.م (هزینه‌های بهره بانکی)
A54: T053 | B54: ۶. وام و تسهیلات بانکی | C54: مسدودی بخشی از نقدینگی شرکت به عنوان وثیقه وام | D54: سپرده‌های سرمایه‌گذاری مسدودی نزد بانک‌ها | E54: موجودی نقد و بانک آزاد سپه | F54: 30000000 | G54: بانک سپه | H54: تا پایان تسویه وام | I54: تفکیک دارایی نقدینگی مقید و مسدودشده از وجوه جاری آزاد شرکت در ترازنامه | J54: استاندارد ۱ حسابداری (افشای دارایی‌های مقید و تضمین‌ها)
A55: T054 | B55: ۶. وام و تسهیلات بانکی | C55: پرداخت علی‌الحساب جریمه و قسط معوق بانکی | D55: تسهیلات بانکی و هزینه جرایم مالیاتی/بانکی (مشروط) | E55: موجودی بانک | F55: 40000000 | G55: بانک عامل وام | H55: روز جاری | I55: طرح سؤال جهت اخذ برگه جزییات کسر بانک: تفکیک اصل بدهی از خسارت تاخیر | J55: قانون عملیات بانکی بدون ربا و استانداردهای هزینه‌های مالی
A56: T055 | B56: ۶. وام و تسهیلات بانکی | C56: شناسایی هزینه سود سالانه تسهیلات تعهدی سررسید نشده | D56: هزینه مالی (سود و بهره تسهیلات) | E56: سود تحقق‌نیافته تسهیلات مالی بانکی | F56: 48000000 | G56: بانک طرف قرارداد تسهیلات | H56: پایان سال مالی | I56: تخصیص سهم هزینه بهره متناسب با دوره زمانی تعهدی طبق جدول استهلاک بدهی | J56: مبنای تعهدی و استاندارد حسابداری ۱۶
A57: T056 | B57: ۶. وام و تسهیلات بانکی | C57: صدور ضمانت‌نامه بانکی مناقصه به همراه ودیعه نقدی | D57: سپرده نقدی ضمانت‌نامه (۱۰۰ م) + هزینه کارمزد (۱۵ م) | E57: موجودی حساب بانک (۱۱۵ م) | F57: 115000000 | G57: بانک صادرکننده ضمانت‌نامه | H57: دوره اعتبار مناقصه | I57: تفکیک کارمزد غیرقابل استرداد از سپرده نقدی مستردشدنی و صدور سند انتظامی ۱ م.ت | J57: دستورالعمل ضمانت‌نامه‌های بانکی بانک مرکزی
A58: T057 | B58: ۶. وام و تسهیلات بانکی | C58: دریافت وام شخصی مدیر و واریز به حساب شرکت جهت نقدینگی | D58: موجودی حساب بانک شرکت | E58: جاری شرکا (یا تسهیلات دریافتی از اشخاص ثالث) | F58: نامشخص | G58: مدیرعامل / بانک اعطا‌کننده وام به مدیر | H58: دوره وام | I58: طرح سؤال: آیا تعهد بازپرداخت متوجه شرکت است یا شخص مدیرعامل؟ | J58: قانون تجارت و استانداردهای تفکیک شخصیت شرکت از سهامدار
A59: T058 | B59: ۶. وام و تسهیلات بانکی | C59: تنزیل بدهی فاکتورها از طریق تسهیلات خرید دین بانکی | D59: بانک (۱۸۲ م) + هزینه مالی تسهیلات خرید دین (۱۸ م) | E59: تسهیلات بانکی خرید دین پرداختنی (۲۰۰ م) | F59: 200000000 | G59: بانک پرداخت‌کننده خرید دین | H59: سررسید فاکتورها | I59: ثبت بدهی بانکی به ارزش اسمی و تخصیص بهره تسهیلات در دوره مالی تسویه | J59: دستورالعمل اجرایی عقد خرید دین بانک مرکزی
A60: T059 | B60: ۶. وام و تسهیلات بانکی | C60: پرداخت کارمزد تمدید حد اعتباری سالانه شرکت در بانک | D60: هزینه مالی و کارمزد خدمات اعتباری بانکی | E60: موجودی حساب بانک ملی | F60: 6500000 | G60: بانک ملی ایران | H60: سال مالی جاری | I60: ثبت در سرفصل هزینه‌های مالی دوره‌ای به عنوان هزینه عملیات تامین مالی | J60: ماده ۱۴۸ بند ۱۸ قانون مالیات‌های مستقیم
A61: T060 | B61: ۶. وام و تسهیلات بانکی | C61: استقراض ربوی از بازار آزاد با سود غیررسمی خارج از شبکه | D61: نامشخص (عدم امکان تایید هزینه مالی ربا) | E61: نامشخص | F61: 200000000 | G61: طلبکار متفرقه بازار آزاد | H61: ماهانه ۵ درصد | I61: هشدار قرمز: سود پرداختی بازار آزاد غیرقابل قبول مالیاتی است و اصل تخلف است | J61: قانون اساسی، فقه اسلامی و ماده ۱۴۸ قانون مالیات‌های مستقیم
A62: T061 | B62: ۷. حقوق، دستمزد و بیمه | C62: ثبت سند ماهانه حقوق و تفکیک کسورات قانونی و پرداختی | D62: هزینه حقوق و دستمزد (۱۸۰ م) | E62: بیمه پرداختنی (۱۳ م) + مالیات حقوق (۸ م) + بانک (۱۵۹ م) | F62: 180000000 | G62: پرسنل، سازمان تامین اجتماعی، امور مالیاتی | H62: اسفند ماه جاری | I62: تفکیک ناخالص حقوق از کسورات کارگر و شناسایی سهم قابل پرداخت به کارکنان | J62: قانون کار، قانون تامین اجتماعی و ماده ۸۵ قانون مالیات‌ها
A63: T062 | B63: ۷. حقوق، دستمزد و بیمه | C63: پرداخت حق بیمه تامین اجتماعی به شعب سازمان تامین اجتماعی | D63: بیمه پرداختنی سازمان تامین اجتماعی | E63: موجودی حساب بانک | F63: 35000000 | G63: سازمان تامین اجتماعی (شعبه کارگاهی) | H63: ماه قبل | I63: تسویه قطعی بدهی بیمه سهم کارگر، کارفرما و بیمه بیکاری | J63: مواد ۲۸ و ۳۶ قانون تامین اجتماعی جمهوری اسلامی ایران
A64: T063 | B64: ۷. حقوق، دستمزد و بیمه | C64: پرداخت مساعده نقدی به پرسنل در اواسط ماه کاری | D64: مساعده حقوق و دستمزد پرسنل (انباردار) | E64: موجودی صندوق نقد شرکت | F64: 10000000 | G64: انباردار شرکت | H64: روز جاری | I64: ثبت در سرفصل مطالبات جاری پرسنل و الزام به تهاتر در فیش حقوقی پایان ماه | J64: قانون کار و استانداردهای دارایی‌های جاری تجاری
A65: T064 | B65: ۷. حقوق، دستمزد و بیمه | C65: پرداخت پاداش نقدی دستی خارج از لیست رسمی حقوق | D65: هزینه پاداش پرسنل (مشروط به بار مالیاتی) | E65: صندوق نقد / حساب شخصی مدیر | F65: 25000000 | G65: کارشناسان فروش شرکت | H65: روز جاری | I65: طرح سؤال و اخطار: پاداش نقدی مشمول مالیات تکلیفی و بیمه است؛ عدم ثبت جریمه دارد | J65: ماده ۸۴ و ۹۱ قانون مالیات‌ها و ماده ۲۸ تامین اجتماعی
A66: T065 | B66: ۷. حقوق، دستمزد و بیمه | C66: محاسبه و پرداخت عیدی و پاداش سالانه به همراه مالیات تکلیفی | D66: هزینه عیدی و پاداش سالانه پرسنل (۲۱۰ م) | E66: مالیات تکلیفی عیدی (۱۵ م) + موجودی بانک (۱۹۵ م) | F66: 210000000 | G66: کل پرسنل و سازمان امور مالیاتی | H66: پایان سال مالی | I66: تفکیک معافیت ماده ۹۱ ق.م.م، کسر مالیات مازاد و پرداخت خالص به کارکنان | J66: قانون مربوط به تعیین عیدی و پاداش سالانه کارگران شاغل
...

Sheet نتایج تست و امتیازدهی
A1: کد سناریو | B1: سرفصل حسابداری (دسته) | C1: تشخیص رویداد (۰-۲۵) | D1: ثبت بدهکار/بستانکار (۰-۲۵) | E1: استخراج مبالغ (۰-۲۰) | F1: طرف‌حساب و تاریخ (۰-۱۵) | G1: مدیریت ابهام/ترکیب (۰-۱۵) | H1: نمره کل (از ۱۰۰) | I1: وضعیت ارزیابی کیفی | J1: وضعیت ثبت در تست کور | L1: ردیف | M1: نوع خطای شناسایی‌شده در موتور هوش مصنوعی | N1: تعداد رخداد | O1: درصد از کل خطاها | P1: سطح ریسک حسابرسی/مالیاتی
A2: ='تست کور'!A2 | B2: ='تست کور'!B2 | C2: =IF(OR('تست کور'!I2="", 'تست کور'!I2="امتناع درست — قاعده‌اش در این فاز ساخته نشده"), "", IF('تست کور'!I2="قبولی کامل (Pass)", 25, IF('تست کور'!J2="خطا در تشخیص ماهیت رویداد", 0, IF('تست کور'!I2="قبولی مشروط (Conditional)", 20, 15)))) | D2: =IF(OR('تست کور'!I2="", 'تست کور'!I2="امتناع درست — قاعده‌اش در این فاز ساخته نشده"), "", IF('تست کور'!I2="قبولی کامل (Pass)", 25, IF(OR('تست کور'!J2="جابجایی یا اشتباه بدهکار/بستانکار", 'تست کور'!I2="خطا در تشخیص سرفصل"), 0, IF('تست کور'!I2="قبولی مشروط (Conditional)", 18, 10)))) | E2: =IF(OR('تست کور'!I2="", 'تست کور'!I2="امتناع درست — قاعده‌اش در این فاز ساخته نشده"), "", IF('تست کور'!I2="قبولی کامل (Pass)", 20, IF(OR('تست کور'!J2="استخراج اشتباه مبلغ یا ارقام", 'تست کور'!I2="خطا در استخراج مبلغ"), 0, IF('تست کور'!I2="قبولی مشروط (Conditional)", 15, 12)))) | F2: =IF(OR('تست کور'!I2="", 'تست کور'!I2="امتناع درست — قاعده‌اش در این فاز ساخته نشده"), "", IF('تست کور'!I2="قبولی کامل (Pass)", 15, IF('تست کور'!J2="عدم تشخیص سررسید یا طرف‌حساب", 0, IF('تست کور'!I2="قبولی مشروط (Conditional)", 11, 10)))) | G2: =IF(OR('تست کور'!I2="", 'تست کور'!I2="امتناع درست — قاعده‌اش در این فاز ساخته نشده"), "", IF('تست کور'!I2="قبولی کامل (Pass)", 15, IF(OR('تست کور'!J2="عدم طرح سؤال در سناریوی مبهم", 'تست کور'!J2="طرح سؤال تکمیلی غلط و توهم اطلاعات", 'تست کور'!I2="سؤال تکمیلی نامربوط/توهم", 'تست کور'!I2="سکوت اشتباه در ابهام"), 0, IF(OR('تست کور'!J2="از قلم افتادن بخش دوم در جمله مرکب", 'تست کور'!I2="عدم تفکیک رویدادها"), 3, IF('تست کور'!I2="قبولی مشروط (Conditional)", 11, 8))))) | H2: =IF(C2="", "", C2+D2+E2+F2+G2) | I2: =IF(H2="", "در انتظار آزمون", IF(H2>=85, "قبولی ممتاز (Passed)", IF(H2>=70, "قبولی متوسط (Acceptable)", IF(H2>=50, "نیازمند بازآموزی (Retrain)", "مردود (Failed)")))) | J2: =IF('تست کور'!I2="", "تست نشده", 'تست کور'!I2) | L2: ۱ | M2: خطا در تشخیص ماهیت رویداد | N2: =COUNTIF('تست کور'!$J$2:$J$121, M2) | O2: =IF(SUM($N$2:$N$9)=0, 0, N2/SUM($N$2:$N$9)) | P2: بسیار بالا (رد دفاتر قانونی)
A3: ='تست کور'!A3 | B3: ='تست کور'!B3 | C3: =IF(OR('تست کور'!I3="", 'تست کور'!I3="امتناع درست — قاعده‌اش در این فاز ساخته نشده"), "", IF('تست کور'!I3="قبولی کامل (Pass)", 25, IF('تست کور'!J3="خطا در تشخیص ماهیت رویداد", 0, IF('تست کور'!I3="قبولی مشروط (Conditional)", 20, 15)))) | D3: =IF(OR('تست کور'!I3="", 'تست کور'!I3="امتناع درست — قاعده‌اش در این فاز ساخته نشده"), "", IF('تست کور'!I3="قبولی کامل (Pass)", 25, IF(OR('تست کور'!J3="جابجایی یا اشتباه بدهکار/بستانکار", 'تست کور'!I3="خطا در تشخیص سرفصل"), 0, IF('تست کور'!I3="قبولی مشروط (Conditional)", 18, 10)))) | E3: =IF(OR('تست کور'!I3="", 'تست کور'!I3="امتناع درست — قاعده‌اش در این فاز ساخته نشده"), "", IF('تست کور'!I3="قبولی کامل (Pass)", 20, IF(OR('تست کور'!J3="استخراج اشتباه مبلغ یا ارقام", 'تست کور'!I3="خطا در استخراج مبلغ"), 0, IF('تست کور'!I3="قبولی مشروط (Conditional)", 15, 12)))) | F3: =IF(OR('تست کور'!I3="", 'تست کور'!I3="امتناع درست — قاعده‌اش در این فاز ساخته نشده"), "", IF('تست کور'!I3="قبولی کامل (Pass)", 15, IF('تست کور'!J3="عدم تشخیص سررسید یا طرف‌حساب", 0, IF('تست کور'!I3="قبولی مشروط (Conditional)", 11, 10)))) | G3: =IF(OR('تست کور'!I3="", 'تست کور'!I3="امتناع درست — قاعده‌اش در این فاز ساخته نشده"), "", IF('تست کور'!I3="قبولی کامل (Pass)", 15, IF(OR('تست کور'!J3="عدم طرح سؤال در سناریوی مبهم", 'تست کور'!J3="طرح سؤال تکمیلی غلط و توهم اطلاعات", 'تست کور'!I3="سؤال تکمیلی نامربوط/توهم", 'تست کور'!I3="سکوت اشتباه در ابهام"), 0, IF(OR('تست کور'!J3="از قلم افتادن بخش دوم در جمله مرکب", 'تست کور'!I3="عدم تفکیک رویدادها"), 3, IF('تست کور'!I3="قبولی مشروط (Conditional)", 11, 8))))) | H3: =IF(C3="", "", C3+D3+E3+F3+G3) | I3: =IF(H3="", "در انتظار آزمون", IF(H3>=85, "قبولی ممتاز (Passed)", IF(H3>=70, "قبولی متوسط (Acceptable)", IF(H3>=50, "نیازمند بازآموزی (Retrain)", "مردود (Failed)")))) | J3: =IF('تست کور'!I3="", "تست نشده", 'تست کور'!I3) | L3: ۲ | M3: جابجایی یا اشتباه بدهکار/بستانکار | N3: =COUNTIF('تست کور'!$J$2:$J$121, M3) | O3: =IF(SUM($N$2:$N$9)=0, 0, N3/SUM($N$2:$N$9)) | P3: بحرانی (برهم خوردن ترازنامه)
A4: ='تست کور'!A4 | B4: ='تست کور'!B4 | C4: =IF(OR('تست کور'!I4="", 'تست کور'!I4="امتناع درست — قاعده‌اش در این فاز ساخته نشده"), "", IF('تست کور'!I4="قبولی کامل (Pass)", 25, IF('تست کور'!J4="خطا در تشخیص ماهیت رویداد", 0, IF('تست کور'!I4="قبولی مشروط (Conditional)", 20, 15)))) | D4: =IF(OR('تست کور'!I4="", 'تست کور'!I4="امتناع درست — قاعده‌اش در این فاز ساخته نشده"), "", IF('تست کور'!I4="قبولی کامل (Pass)", 25, IF(OR('تست کور'!J4="جابجایی یا اشتباه بدهکار/بستانکار", 'تست کور'!I4="خطا در تشخیص سرفصل"), 0, IF('تست کور'!I4="قبولی مشروط (Conditional)", 18, 10)))) | E4: =IF(OR('تست کور'!I4="", 'تست کور'!I4="امتناع درست — قاعده‌اش در این فاز ساخته نشده"), "", IF('تست کور'!I4="قبولی کامل (Pass)", 20, IF(OR('تست کور'!J4="استخراج اشتباه مبلغ یا ارقام", 'تست کور'!I4="خطا در استخراج مبلغ"), 0, IF('تست کور'!I4="قبولی مشروط (Conditional)", 15, 12)))) | F4: =IF(OR('تست کور'!I4="", 'تست کور'!I4="امتناع درست — قاعده‌اش در این فاز ساخته نشده"), "", IF('تست کور'!I4="قبولی کامل (Pass)", 15, IF('تست کور'!J4="عدم تشخیص سررسید یا طرف‌حساب", 0, IF('تست کور'!I4="قبولی مشروط (Conditional)", 11, 10)))) | G4: =IF(OR('تست کور'!I4="", 'تست کور'!I4="امتناع درست — قاعده‌اش در این فاز ساخته نشده"), "", IF('تست کور'!I4="قبولی کامل (Pass)", 15, IF(OR('تست کور'!J4="عدم طرح سؤال در سناریوی مبهم", 'تست کور'!J4="طرح سؤال تکمیلی غلط و توهم اطلاعات", 'تست کور'!I4="سؤال تکمیلی نامربوط/توهم", 'تست کور'!I4="سکوت اشتباه در ابهام"), 0, IF(OR('تست کور'!J4="از قلم افتادن بخش دوم در جمله مرکب", 'تست کور'!I4="عدم تفکیک رویدادها"), 3, IF('تست کور'!I4="قبولی مشروط (Conditional)", 11, 8))))) | H4: =IF(C4="", "", C4+D4+E4+F4+G4) | I4: =IF(H4="", "در انتظار آزمون", IF(H4>=85, "قبولی ممتاز (Passed)", IF(H4>=70, "قبولی متوسط (Acceptable)", IF(H4>=50, "نیازمند بازآموزی (Retrain)", "مردود (Failed)")))) | J4: =IF('تست کور'!I4="", "تست نشده", 'تست کور'!I4) | L4: ۳ | M4: استخراج اشتباه مبلغ یا ارقام | N4: =COUNTIF('تست کور'!$J$2:$J$121, M4) | O4: =IF(SUM($N$2:$N$9)=0, 0, N4/SUM($N$2:$N$9)) | P4: بحرانی (مغایرت مالی شدید)
A5: ='تست کور'!A5 | B5: ='تست کور'!B5 | C5: =IF(OR('تست کور'!I5="", 'تست کور'!I5="امتناع درست — قاعده‌اش در این فاز ساخته نشده"), "", IF('تست کور'!I5="قبولی کامل (Pass)", 25, IF('تست کور'!J5="خطا در تشخیص ماهیت رویداد", 0, IF('تست کور'!I5="قبولی مشروط (Conditional)", 20, 15)))) | D5: =IF(OR('تست کور'!I5="", 'تست کور'!I5="امتناع درست — قاعده‌اش در این فاز ساخته نشده"), "", IF('تست کور'!I5="قبولی کامل (Pass)", 25, IF(OR('تست کور'!J5="جابجایی یا اشتباه بدهکار/بستانکار", 'تست کور'!I5="خطا در تشخیص سرفصل"), 0, IF('تست کور'!I5="قبولی مشروط (Conditional)", 18, 10)))) | E5: =IF(OR('تست کور'!I5="", 'تست کور'!I5="امتناع درست — قاعده‌اش در این فاز ساخته نشده"), "", IF('تست کور'!I5="قبولی کامل (Pass)", 20, IF(OR('تست کور'!J5="استخراج اشتباه مبلغ یا ارقام", 'تست کور'!I5="خطا در استخراج مبلغ"), 0, IF('تست کور'!I5="قبولی مشروط (Conditional)", 15, 12)))) | F5: =IF(OR('تست کور'!I5="", 'تست کور'!I5="امتناع درست — قاعده‌اش در این فاز ساخته نشده"), "", IF('تست کور'!I5="قبولی کامل (Pass)", 15, IF('تست کور'!J5="عدم تشخیص سررسید یا طرف‌حساب", 0, IF('تست کور'!I5="قبولی مشروط (Conditional)", 11, 10)))) | G5: =IF(OR('تست کور'!I5="", 'تست کور'!I5="امتناع درست — قاعده‌اش در این فاز ساخته نشده"), "", IF('تست کور'!I5="قبولی کامل (Pass)", 15, IF(OR('تست کور'!J5="عدم طرح سؤال در سناریوی مبهم", 'تست کور'!J5="طرح سؤال تکمیلی غلط و توهم اطلاعات", 'تست کور'!I5="سؤال تکمیلی نامربوط/توهم", 'تست کور'!I5="سکوت اشتباه در ابهام"), 0, IF(OR('تست کور'!J5="از قلم افتادن بخش دوم در جمله مرکب", 'تست کور'!I5="عدم تفکیک رویدادها"), 3, IF('تست کور'!I5="قبولی مشروط (Conditional)", 11, 8))))) | H5: =IF(C5="", "", C5+D5+E5+F5+G5) | I5: =IF(H5="", "در انتظار آزمون", IF(H5>=85, "قبولی ممتاز (Passed)", IF(H5>=70, "قبولی متوسط (Acceptable)", IF(H5>=50, "نیازمند بازآموزی (Retrain)", "مردود (Failed)")))) | J5: =IF('تست کور'!I5="", "تست نشده", 'تست کور'!I5) | L5: ۴ | M5: از قلم افتادن بخش دوم در جمله مرکب | N5: =COUNTIF('تست کور'!$J$2:$J$121, M5) | O5: =IF(SUM($N$2:$N$9)=0, 0, N5/SUM($N$2:$N$9)) | P5: بالا (تحریف واقعیت معامله)
A6: ='تست کور'!A6 | B6: ='تست کور'!B6 | C6: =IF(OR('تست کور'!I6="", 'تست کور'!I6="امتناع درست — قاعده‌اش در این فاز ساخته نشده"), "", IF('تست کور'!I6="قبولی کامل (Pass)", 25, IF('تست کور'!J6="خطا در تشخیص ماهیت رویداد", 0, IF('تست کور'!I6="قبولی مشروط (Conditional)", 20, 15)))) | D6: =IF(OR('تست کور'!I6="", 'تست کور'!I6="امتناع درست — قاعده‌اش در این فاز ساخته نشده"), "", IF('تست کور'!I6="قبولی کامل (Pass)", 25, IF(OR('تست کور'!J6="جابجایی یا اشتباه بدهکار/بستانکار", 'تست کور'!I6="خطا در تشخیص سرفصل"), 0, IF('تست کور'!I6="قبولی مشروط (Conditional)", 18, 10)))) | E6: =IF(OR('تست کور'!I6="", 'تست کور'!I6="امتناع درست — قاعده‌اش در این فاز ساخته نشده"), "", IF('تست کور'!I6="قبولی کامل (Pass)", 20, IF(OR('تست کور'!J6="استخراج اشتباه مبلغ یا ارقام", 'تست کور'!I6="خطا در استخراج مبلغ"), 0, IF('تست کور'!I6="قبولی مشروط (Conditional)", 15, 12)))) | F6: =IF(OR('تست کور'!I6="", 'تست کور'!I6="امتناع درست — قاعده‌اش در این فاز ساخته نشده"), "", IF('تست کور'!I6="قبولی کامل (Pass)", 15, IF('تست کور'!J6="عدم تشخیص سررسید یا طرف‌حساب", 0, IF('تست کور'!I6="قبولی مشروط (Conditional)", 11, 10)))) | G6: =IF(OR('تست کور'!I6="", 'تست کور'!I6="امتناع درست — قاعده‌اش در این فاز ساخته نشده"), "", IF('تست کور'!I6="قبولی کامل (Pass)", 15, IF(OR('تست کور'!J6="عدم طرح سؤال در سناریوی مبهم", 'تست کور'!J6="طرح سؤال تکمیلی غلط و توهم اطلاعات", 'تست کور'!I6="سؤال تکمیلی نامربوط/توهم", 'تست کور'!I6="سکوت اشتباه در ابهام"), 0, IF(OR('تست کور'!J6="از قلم افتادن بخش دوم در جمله مرکب", 'تست کور'!I6="عدم تفکیک رویدادها"), 3, IF('تست کور'!I6="قبولی مشروط (Conditional)", 11, 8))))) | H6: =IF(C6="", "", C6+D6+E6+F6+G6) | I6: =IF(H6="", "در انتظار آزمون", IF(H6>=85, "قبولی ممتاز (Passed)", IF(H6>=70, "قبولی متوسط (Acceptable)", IF(H6>=50, "نیازمند بازآموزی (Retrain)", "مردود (Failed)")))) | J6: =IF('تست کور'!I6="", "تست نشده", 'تست کور'!I6) | L6: ۵ | M6: عدم طرح سؤال در سناریوی مبهم | N6: =COUNTIF('تست کور'!$J$2:$J$121, M6) | O6: =IF(SUM($N$2:$N$9)=0, 0, N6/SUM($N$2:$N$9)) | P6: بالا (ثبت خودسرانه بدون مدرک)
A7: ='تست کور'!A7 | B7: ='تست کور'!B7 | C7: =IF(OR('تست کور'!I7="", 'تست کور'!I7="امتناع درست — قاعده‌اش در این فاز ساخته نشده"), "", IF('تست کور'!I7="قبولی کامل (Pass)", 25, IF('تست کور'!J7="خطا در تشخیص ماهیت رویداد", 0, IF('تست کور'!I7="قبولی مشروط (Conditional)", 20, 15)))) | D7: =IF(OR('تست کور'!I7="", 'تست کور'!I7="امتناع درست — قاعده‌اش در این فاز ساخته نشده"), "", IF('تست کور'!I7="قبولی کامل (Pass)", 25, IF(OR('تست کور'!J7="جابجایی یا اشتباه بدهکار/بستانکار", 'تست کور'!I7="خطا در تشخیص سرفصل"), 0, IF('تست کور'!I7="قبولی مشروط (Conditional)", 18, 10)))) | E7: =IF(OR('تست کور'!I7="", 'تست کور'!I7="امتناع درست — قاعده‌اش در این فاز ساخته نشده"), "", IF('تست کور'!I7="قبولی کامل (Pass)", 20, IF(OR('تست کور'!J7="استخراج اشتباه مبلغ یا ارقام", 'تست کور'!I7="خطا در استخراج مبلغ"), 0, IF('تست کور'!I7="قبولی مشروط (Conditional)", 15, 12)))) | F7: =IF(OR('تست کور'!I7="", 'تست کور'!I7="امتناع درست — قاعده‌اش در این فاز ساخته نشده"), "", IF('تست کور'!I7="قبولی کامل (Pass)", 15, IF('تست کور'!J7="عدم تشخیص سررسید یا طرف‌حساب", 0, IF('تست کور'!I7="قبولی مشروط (Conditional)", 11, 10)))) | G7: =IF(OR('تست کور'!I7="", 'تست کور'!I7="امتناع درست — قاعده‌اش در این فاز ساخته نشده"), "", IF('تست کور'!I7="قبولی کامل (Pass)", 15, IF(OR('تست کور'!J7="عدم طرح سؤال در سناریوی مبهم", 'تست کور'!J7="طرح سؤال تکمیلی غلط و توهم اطلاعات", 'تست کور'!I7="سؤال تکمیلی نامربوط/توهم", 'تست کور'!I7="سکوت اشتباه در ابهام"), 0, IF(OR('تست کور'!J7="از قلم افتادن بخش دوم در جمله مرکب", 'تست کور'!I7="عدم تفکیک رویدادها"), 3, IF('تست کور'!I7="قبولی مشروط (Conditional)", 11, 8))))) | H7: =IF(C7="", "", C7+D7+E7+F7+G7) | I7: =IF(H7="", "در انتظار آزمون", IF(H7>=85, "قبولی ممتاز (Passed)", IF(H7>=70, "قبولی متوسط (Acceptable)", IF(H7>=50, "نیازمند بازآموزی (Retrain)", "مردود (Failed)")))) | J7: =IF('تست کور'!I7="", "تست نشده", 'تست کور'!I7) | L7: ۶ | M7: طرح سؤال تکمیلی غلط و توهم اطلاعات | N7: =COUNTIF('تست کور'!$J$2:$J$121, M7) | O7: =IF(SUM($N$2:$N$9)=0, 0, N7/SUM($N$2:$N$9)) | P7: متوسط (تضعیف تجربه کاربری)
A8: ='تست کور'!A8 | B8: ='تست کور'!B8 | C8: =IF(OR('تست کور'!I8="", 'تست کور'!I8="امتناع درست — قاعده‌اش در این فاز ساخته نشده"), "", IF('تست کور'!I8="قبولی کامل (Pass)", 25, IF('تست کور'!J8="خطا در تشخیص ماهیت رویداد", 0, IF('تست کور'!I8="قبولی مشروط (Conditional)", 20, 15)))) | D8: =IF(OR('تست کور'!I8="", 'تست کور'!I8="امتناع درست — قاعده‌اش در این فاز ساخته نشده"), "", IF('تست کور'!I8="قبولی کامل (Pass)", 25, IF(OR('تست کور'!J8="جابجایی یا اشتباه بدهکار/بستانکار", 'تست کور'!I8="خطا در تشخیص سرفصل"), 0, IF('تست کور'!I8="قبولی مشروط (Conditional)", 18, 10)))) | E8: =IF(OR('تست کور'!I8="", 'تست کور'!I8="امتناع درست — قاعده‌اش در این فاز ساخته نشده"), "", IF('تست کور'!I8="قبولی کامل (Pass)", 20, IF(OR('تست کور'!J8="استخراج اشتباه مبلغ یا ارقام", 'تست کور'!I8="خطا در استخراج مبلغ"), 0, IF('تست کور'!I8="قبولی مشروط (Conditional)", 15, 12)))) | F8: =IF(OR('تست کور'!I8="", 'تست کور'!I8="امتناع درست — قاعده‌اش در این فاز ساخته نشده"), "", IF('تست کور'!I8="قبولی کامل (Pass)", 15, IF('تست کور'!J8="عدم تشخیص سررسید یا طرف‌حساب", 0, IF('تست کور'!I8="قبولی مشروط (Conditional)", 11, 10)))) | G8: =IF(OR('تست کور'!I8="", 'تست کور'!I8="امتناع درست — قاعده‌اش در این فاز ساخته نشده"), "", IF('تست کور'!I8="قبولی کامل (Pass)", 15, IF(OR('تست کور'!J8="عدم طرح سؤال در سناریوی مبهم", 'تست کور'!J8="طرح سؤال تکمیلی غلط و توهم اطلاعات", 'تست کور'!I8="سؤال تکمیلی نامربوط/توهم", 'تست کور'!I8="سکوت اشتباه در ابهام"), 0, IF(OR('تست کور'!J8="از قلم افتادن بخش دوم در جمله مرکب", 'تست کور'!I8="عدم تفکیک رویدادها"), 3, IF('تست کور'!I8="قبولی مشروط (Conditional)", 11, 8))))) | H8: =IF(C8="", "", C8+D8+E8+F8+G8) | I8: =IF(H8="", "در انتظار آزمون", IF(H8>=85, "قبولی ممتاز (Passed)", IF(H8>=70, "قبولی متوسط (Acceptable)", IF(H8>=50, "نیازمند بازآموزی (Retrain)", "مردود (Failed)")))) | J8: =IF('تست کور'!I8="", "تست نشده", 'تست کور'!I8) | L8: ۷ | M8: عدم تشخیص سررسید یا طرف‌حساب | N8: =COUNTIF('تست کور'!$J$2:$J$121, M8) | O8: =IF(SUM($N$2:$N$9)=0, 0, N8/SUM($N$2:$N$9)) | P8: بالا (مشکل در وصول مطالبات)
A9: ='تست کور'!A9 | B9: ='تست کور'!B9 | C9: =IF(OR('تست کور'!I9="", 'تست کور'!I9="امتناع درست — قاعده‌اش در این فاز ساخته نشده"), "", IF('تست کور'!I9="قبولی کامل (Pass)", 25, IF('تست کور'!J9="خطا در تشخیص ماهیت رویداد", 0, IF('تست کور'!I9="قبولی مشروط (Conditional)", 20, 15)))) | D9: =IF(OR('تست کور'!I9="", 'تست کور'!I9="امتناع درست — قاعده‌اش در این فاز ساخته نشده"), "", IF('تست کور'!I9="قبولی کامل (Pass)", 25, IF(OR('تست کور'!J9="جابجایی یا اشتباه بدهکار/بستانکار", 'تست کور'!I9="خطا در تشخیص سرفصل"), 0, IF('تست کور'!I9="قبولی مشروط (Conditional)", 18, 10)))) | E9: =IF(OR('تست کور'!I9="", 'تست کور'!I9="امتناع درست — قاعده‌اش در این فاز ساخته نشده"), "", IF('تست کور'!I9="قبولی کامل (Pass)", 20, IF(OR('تست کور'!J9="استخراج اشتباه مبلغ یا ارقام", 'تست کور'!I9="خطا در استخراج مبلغ"), 0, IF('تست کور'!I9="قبولی مشروط (Conditional)", 15, 12)))) | F9: =IF(OR('تست کور'!I9="", 'تست کور'!I9="امتناع درست — قاعده‌اش در این فاز ساخته نشده"), "", IF('تست کور'!I9="قبولی کامل (Pass)", 15, IF('تست کور'!J9="عدم تشخیص سررسید یا طرف‌حساب", 0, IF('تست کور'!I9="قبولی مشروط (Conditional)", 11, 10)))) | G9: =IF(OR('تست کور'!I9="", 'تست کور'!I9="امتناع درست — قاعده‌اش در این فاز ساخته نشده"), "", IF('تست کور'!I9="قبولی کامل (Pass)", 15, IF(OR('تست کور'!J9="عدم طرح سؤال در سناریوی مبهم", 'تست کور'!J9="طرح سؤال تکمیلی غلط و توهم اطلاعات", 'تست کور'!I9="سؤال تکمیلی نامربوط/توهم", 'تست کور'!I9="سکوت اشتباه در ابهام"), 0, IF(OR('تست کور'!J9="از قلم افتادن بخش دوم در جمله مرکب", 'تست کور'!I9="عدم تفکیک رویدادها"), 3, IF('تست کور'!I9="قبولی مشروط (Conditional)", 11, 8))))) | H9: =IF(C9="", "", C9+D9+E9+F9+G9) | I9: =IF(H9="", "در انتظار آزمون", IF(H9>=85, "قبولی ممتاز (Passed)", IF(H9>=70, "قبولی متوسط (Acceptable)", IF(H9>=50, "نیازمند بازآموزی (Retrain)", "مردود (Failed)")))) | J9: =IF('تست کور'!I9="", "تست نشده", 'تست کور'!I9) | L9: ۸ | M9: عدم رعایت کنترل‌های داخلی و مالیاتی | N9: =COUNTIF('تست کور'!$J$2:$J$121, M9) | O9: =IF(SUM($N$2:$N$9)=0, 0, N9/SUM($N$2:$N$9)) | P9: بسیار بالا (جرایم ماده ۱۶۹ و مودیان)
A10: ='تست کور'!A10 | B10: ='تست کور'!B10 | C10: =IF(OR('تست کور'!I10="", 'تست کور'!I10="امتناع درست — قاعده‌اش در این فاز ساخته نشده"), "", IF('تست کور'!I10="قبولی کامل (Pass)", 25, IF('تست کور'!J10="خطا در تشخیص ماهیت رویداد", 0, IF('تست کور'!I10="قبولی مشروط (Conditional)", 20, 15)))) | D10: =IF(OR('تست کور'!I10="", 'تست کور'!I10="امتناع درست — قاعده‌اش در این فاز ساخته نشده"), "", IF('تست کور'!I10="قبولی کامل (Pass)", 25, IF(OR('تست کور'!J10="جابجایی یا اشتباه بدهکار/بستانکار", 'تست کور'!I10="خطا در تشخیص سرفصل"), 0, IF('تست کور'!I10="قبولی مشروط (Conditional)", 18, 10)))) | E10: =IF(OR('تست کور'!I10="", 'تست کور'!I10="امتناع درست — قاعده‌اش در این فاز ساخته نشده"), "", IF('تست کور'!I10="قبولی کامل (Pass)", 20, IF(OR('تست کور'!J10="استخراج اشتباه مبلغ یا ارقام", 'تست کور'!I10="خطا در استخراج مبلغ"), 0, IF('تست کور'!I10="قبولی مشروط (Conditional)", 15, 12)))) | F10: =IF(OR('تست کور'!I10="", 'تست کور'!I10="امتناع درست — قاعده‌اش در این فاز ساخته نشده"), "", IF('تست کور'!I10="قبولی کامل (Pass)", 15, IF('تست کور'!J10="عدم تشخیص سررسید یا طرف‌حساب", 0, IF('تست کور'!I10="قبولی مشروط (Conditional)", 11, 10)))) | G10: =IF(OR('تست کور'!I10="", 'تست کور'!I10="امتناع درست — قاعده‌اش در این فاز ساخته نشده"), "", IF('تست کور'!I10="قبولی کامل (Pass)", 15, IF(OR('تست کور'!J10="عدم طرح سؤال در سناریوی مبهم", 'تست کور'!J10="طرح سؤال تکمیلی غلط و توهم اطلاعات", 'تست کور'!I10="سؤال تکمیلی نامربوط/توهم", 'تست کور'!I10="سکوت اشتباه در ابهام"), 0, IF(OR('تست کور'!J10="از قلم افتادن بخش دوم در جمله مرکب", 'تست کور'!I10="عدم تفکیک رویدادها"), 3, IF('تست کور'!I10="قبولی مشروط (Conditional)", 11, 8))))) | H10: =IF(C10="", "", C10+D10+E10+F10+G10) | I10: =IF(H10="", "در انتظار آزمون", IF(H10>=85, "قبولی ممتاز (Passed)", IF(H10>=70, "قبولی متوسط (Acceptable)", IF(H10>=50, "نیازمند بازآموزی (Retrain)", "مردود (Failed)")))) | J10: =IF('تست کور'!I10="", "تست نشده", 'تست کور'!I10) | L10: - | M10: مجموع خطاهای شناسایی‌شده | N10: =SUM(N2:N9) | O10: =SUM(O2:O9) | P10: شاخص قابلیت اطمینان سیستم
A11: ='تست کور'!A11 | B11: ='تست کور'!B11 | C11: =IF(OR('تست کور'!I11="", 'تست کور'!I11="امتناع درست — قاعده‌اش در این فاز ساخته نشده"), "", IF('تست کور'!I11="قبولی کامل (Pass)", 25, IF('تست کور'!J11="خطا در تشخیص ماهیت رویداد", 0, IF('تست کور'!I11="قبولی مشروط (Conditional)", 20, 15)))) | D11: =IF(OR('تست کور'!I11="", 'تست کور'!I11="امتناع درست — قاعده‌اش در این فاز ساخته نشده"), "", IF('تست کور'!I11="قبولی کامل (Pass)", 25, IF(OR('تست کور'!J11="جابجایی یا اشتباه بدهکار/بستانکار", 'تست کور'!I11="خطا در تشخیص سرفصل"), 0, IF('تست کور'!I11="قبولی مشروط (Conditional)", 18, 10)))) | E11: =IF(OR('تست کور'!I11="", 'تست کور'!I11="امتناع درست — قاعده‌اش در این فاز ساخته نشده"), "", IF('تست کور'!I11="قبولی کامل (Pass)", 20, IF(OR('تست کور'!J11="استخراج اشتباه مبلغ یا ارقام", 'تست کور'!I11="خطا در استخراج مبلغ"), 0, IF('تست کور'!I11="قبولی مشروط (Conditional)", 15, 12)))) | F11: =IF(OR('تست کور'!I11="", 'تست کور'!I11="امتناع درست — قاعده‌اش در این فاز ساخته نشده"), "", IF('تست کور'!I11="قبولی کامل (Pass)", 15, IF('تست کور'!J11="عدم تشخیص سررسید یا طرف‌حساب", 0, IF('تست کور'!I11="قبولی مشروط (Conditional)", 11, 10)))) | G11: =IF(OR('تست کور'!I11="", 'تست کور'!I11="امتناع درست — قاعده‌اش در این فاز ساخته نشده"), "", IF('تست کور'!I11="قبولی کامل (Pass)", 15, IF(OR('تست کور'!J11="عدم طرح سؤال در سناریوی مبهم", 'تست کور'!J11="طرح سؤال تکمیلی غلط و توهم اطلاعات", 'تست کور'!I11="سؤال تکمیلی نامربوط/توهم", 'تست کور'!I11="سکوت اشتباه در ابهام"), 0, IF(OR('تست کور'!J11="از قلم افتادن بخش دوم در جمله مرکب", 'تست کور'!I11="عدم تفکیک رویدادها"), 3, IF('تست کور'!I11="قبولی مشروط (Conditional)", 11, 8))))) | H11: =IF(C11="", "", C11+D11+E11+F11+G11) | I11: =IF(H11="", "در انتظار آزمون", IF(H11>=85, "قبولی ممتاز (Passed)", IF(H11>=70, "قبولی متوسط (Acceptable)", IF(H11>=50, "نیازمند بازآموزی (Retrain)", "مردود (Failed)")))) | J11: =IF('تست کور'!I11="", "تست نشده", 'تست کور'!I11) | L11: - | M11: نرخ سناریوهای بدون خطا (Zero-Defect) | N11: =COUNTIF('تست کور'!$J$2:$J$121, "بدون خطا") | O11: =IF(COUNTA('تست کور'!$I$2:$I$121)=0, 0, N11/COUNTA('تست کور'!$I$2:$I$121)) | P11: هدف کیفی: بالای ۹۰٪
A12: ='تست کور'!A12 | B12: ='تست کور'!B12 | C12: =IF(OR('تست کور'!I12="", 'تست کور'!I12="امتناع درست — قاعده‌اش در این فاز ساخته نشده"), "", IF('تست کور'!I12="قبولی کامل (Pass)", 25, IF('تست کور'!J12="خطا در تشخیص ماهیت رویداد", 0, IF('تست کور'!I12="قبولی مشروط (Conditional)", 20, 15)))) | D12: =IF(OR('تست کور'!I12="", 'تست کور'!I12="امتناع درست — قاعده‌اش در این فاز ساخته نشده"), "", IF('تست کور'!I12="قبولی کامل (Pass)", 25, IF(OR('تست کور'!J12="جابجایی یا اشتباه بدهکار/بستانکار", 'تست کور'!I12="خطا در تشخیص سرفصل"), 0, IF('تست کور'!I12="قبولی مشروط (Conditional)", 18, 10)))) | E12: =IF(OR('تست کور'!I12="", 'تست کور'!I12="امتناع درست — قاعده‌اش در این فاز ساخته نشده"), "", IF('تست کور'!I12="قبولی کامل (Pass)", 20, IF(OR('تست کور'!J12="استخراج اشتباه مبلغ یا ارقام", 'تست کور'!I12="خطا در استخراج مبلغ"), 0, IF('تست کور'!I12="قبولی مشروط (Conditional)", 15, 12)))) | F12: =IF(OR('تست کور'!I12="", 'تست کور'!I12="امتناع درست — قاعده‌اش در این فاز ساخته نشده"), "", IF('تست کور'!I12="قبولی کامل (Pass)", 15, IF('تست کور'!J12="عدم تشخیص سررسید یا طرف‌حساب", 0, IF('تست کور'!I12="قبولی مشروط (Conditional)", 11, 10)))) | G12: =IF(OR('تست کور'!I12="", 'تست کور'!I12="امتناع درست — قاعده‌اش در این فاز ساخته نشده"), "", IF('تست کور'!I12="قبولی کامل (Pass)", 15, IF(OR('تست کور'!J12="عدم طرح سؤال در سناریوی مبهم", 'تست کور'!J12="طرح سؤال تکمیلی غلط و توهم اطلاعات", 'تست کور'!I12="سؤال تکمیلی نامربوط/توهم", 'تست کور'!I12="سکوت اشتباه در ابهام"), 0, IF(OR('تست کور'!J12="از قلم افتادن بخش دوم در جمله مرکب", 'تست کور'!I12="عدم تفکیک رویدادها"), 3, IF('تست کور'!I12="قبولی مشروط (Conditional)", 11, 8))))) | H12: =IF(C12="", "", C12+D12+E12+F12+G12) | I12: =IF(H12="", "در انتظار آزمون", IF(H12>=85, "قبولی ممتاز (Passed)", IF(H12>=70, "قبولی متوسط (Acceptable)", IF(H12>=50, "نیازمند بازآموزی (Retrain)", "مردود (Failed)")))) | J12: =IF('تست کور'!I12="", "تست نشده", 'تست کور'!I12)
A13: ='تست کور'!A13 | B13: ='تست کور'!B13 | C13: =IF(OR('تست کور'!I13="", 'تست کور'!I13="امتناع درست — قاعده‌اش در این فاز ساخته نشده"), "", IF('تست کور'!I13="قبولی کامل (Pass)", 25, IF('تست کور'!J13="خطا در تشخیص ماهیت رویداد", 0, IF('تست کور'!I13="قبولی مشروط (Conditional)", 20, 15)))) | D13: =IF(OR('تست کور'!I13="", 'تست کور'!I13="امتناع درست — قاعده‌اش در این فاز ساخته نشده"), "", IF('تست کور'!I13="قبولی کامل (Pass)", 25, IF(OR('تست کور'!J13="جابجایی یا اشتباه بدهکار/بستانکار", 'تست کور'!I13="خطا در تشخیص سرفصل"), 0, IF('تست کور'!I13="قبولی مشروط (Conditional)", 18, 10)))) | E13: =IF(OR('تست کور'!I13="", 'تست کور'!I13="امتناع درست — قاعده‌اش در این فاز ساخته نشده"), "", IF('تست کور'!I13="قبولی کامل (Pass)", 20, IF(OR('تست کور'!J13="استخراج اشتباه مبلغ یا ارقام", 'تست کور'!I13="خطا در استخراج مبلغ"), 0, IF('تست کور'!I13="قبولی مشروط (Conditional)", 15, 12)))) | F13: =IF(OR('تست کور'!I13="", 'تست کور'!I13="امتناع درست — قاعده‌اش در این فاز ساخته نشده"), "", IF('تست کور'!I13="قبولی کامل (Pass)", 15, IF('تست کور'!J13="عدم تشخیص سررسید یا طرف‌حساب", 0, IF('تست کور'!I13="قبولی مشروط (Conditional)", 11, 10)))) | G13: =IF(OR('تست کور'!I13="", 'تست کور'!I13="امتناع درست — قاعده‌اش در این فاز ساخته نشده"), "", IF('تست کور'!I13="قبولی کامل (Pass)", 15, IF(OR('تست کور'!J13="عدم طرح سؤال در سناریوی مبهم", 'تست کور'!J13="طرح سؤال تکمیلی غلط و توهم اطلاعات", 'تست کور'!I13="سؤال تکمیلی نامربوط/توهم", 'تست کور'!I13="سکوت اشتباه در ابهام"), 0, IF(OR('تست کور'!J13="از قلم افتادن بخش دوم در جمله مرکب", 'تست کور'!I13="عدم تفکیک رویدادها"), 3, IF('تست کور'!I13="قبولی مشروط (Conditional)", 11, 8))))) | H13: =IF(C13="", "", C13+D13+E13+F13+G13) | I13: =IF(H13="", "در انتظار آزمون", IF(H13>=85, "قبولی ممتاز (Passed)", IF(H13>=70, "قبولی متوسط (Acceptable)", IF(H13>=50, "نیازمند بازآموزی (Retrain)", "مردود (Failed)")))) | J13: =IF('تست کور'!I13="", "تست نشده", 'تست کور'!I13)
A14: ='تست کور'!A14 | B14: ='تست کور'!B14 | C14: =IF(OR('تست کور'!I14="", 'تست کور'!I14="امتناع درست — قاعده‌اش در این فاز ساخته نشده"), "", IF('تست کور'!I14="قبولی کامل (Pass)", 25, IF('تست کور'!J14="خطا در تشخیص ماهیت رویداد", 0, IF('تست کور'!I14="قبولی مشروط (Conditional)", 20, 15)))) | D14: =IF(OR('تست کور'!I14="", 'تست کور'!I14="امتناع درست — قاعده‌اش در این فاز ساخته نشده"), "", IF('تست کور'!I14="قبولی کامل (Pass)", 25, IF(OR('تست کور'!J14="جابجایی یا اشتباه بدهکار/بستانکار", 'تست کور'!I14="خطا در تشخیص سرفصل"), 0, IF('تست کور'!I14="قبولی مشروط (Conditional)", 18, 10)))) | E14: =IF(OR('تست کور'!I14="", 'تست کور'!I14="امتناع درست — قاعده‌اش در این فاز ساخته نشده"), "", IF('تست کور'!I14="قبولی کامل (Pass)", 20, IF(OR('تست کور'!J14="استخراج اشتباه مبلغ یا ارقام", 'تست کور'!I14="خطا در استخراج مبلغ"), 0, IF('تست کور'!I14="قبولی مشروط (Conditional)", 15, 12)))) | F14: =IF(OR('تست کور'!I14="", 'تست کور'!I14="امتناع درست — قاعده‌اش در این فاز ساخته نشده"), "", IF('تست کور'!I14="قبولی کامل (Pass)", 15, IF('تست کور'!J14="عدم تشخیص سررسید یا طرف‌حساب", 0, IF('تست کور'!I14="قبولی مشروط (Conditional)", 11, 10)))) | G14: =IF(OR('تست کور'!I14="", 'تست کور'!I14="امتناع درست — قاعده‌اش در این فاز ساخته نشده"), "", IF('تست کور'!I14="قبولی کامل (Pass)", 15, IF(OR('تست کور'!J14="عدم طرح سؤال در سناریوی مبهم", 'تست کور'!J14="طرح سؤال تکمیلی غلط و توهم اطلاعات", 'تست کور'!I14="سؤال تکمیلی نامربوط/توهم", 'تست کور'!I14="سکوت اشتباه در ابهام"), 0, IF(OR('تست کور'!J14="از قلم افتادن بخش دوم در جمله مرکب", 'تست کور'!I14="عدم تفکیک رویدادها"), 3, IF('تست کور'!I14="قبولی مشروط (Conditional)", 11, 8))))) | H14: =IF(C14="", "", C14+D14+E14+F14+G14) | I14: =IF(H14="", "در انتظار آزمون", IF(H14>=85, "قبولی ممتاز (Passed)", IF(H14>=70, "قبولی متوسط (Acceptable)", IF(H14>=50, "نیازمند بازآموزی (Retrain)", "مردود (Failed)")))) | J14: =IF('تست کور'!I14="", "تست نشده", 'تست کور'!I14)
A15: ='تست کور'!A15 | B15: ='تست کور'!B15 | C15: =IF(OR('تست کور'!I15="", 'تست کور'!I15="امتناع درست — قاعده‌اش در این فاز ساخته نشده"), "", IF('تست کور'!I15="قبولی کامل (Pass)", 25, IF('تست کور'!J15="خطا در تشخیص ماهیت رویداد", 0, IF('تست کور'!I15="قبولی مشروط (Conditional)", 20, 15)))) | D15: =IF(OR('تست کور'!I15="", 'تست کور'!I15="امتناع درست — قاعده‌اش در این فاز ساخته نشده"), "", IF('تست کور'!I15="قبولی کامل (Pass)", 25, IF(OR('تست کور'!J15="جابجایی یا اشتباه بدهکار/بستانکار", 'تست کور'!I15="خطا در تشخیص سرفصل"), 0, IF('تست کور'!I15="قبولی مشروط (Conditional)", 18, 10)))) | E15: =IF(OR('تست کور'!I15="", 'تست کور'!I15="امتناع درست — قاعده‌اش در این فاز ساخته نشده"), "", IF('تست کور'!I15="قبولی کامل (Pass)", 20, IF(OR('تست کور'!J15="استخراج اشتباه مبلغ یا ارقام", 'تست کور'!I15="خطا در استخراج مبلغ"), 0, IF('تست کور'!I15="قبولی مشروط (Conditional)", 15, 12)))) | F15: =IF(OR('تست کور'!I15="", 'تست کور'!I15="امتناع درست — قاعده‌اش در این فاز ساخته نشده"), "", IF('تست کور'!I15="قبولی کامل (Pass)", 15, IF('تست کور'!J15="عدم تشخیص سررسید یا طرف‌حساب", 0, IF('تست کور'!I15="قبولی مشروط (Conditional)", 11, 10)))) | G15: =IF(OR('تست کور'!I15="", 'تست کور'!I15="امتناع درست — قاعده‌اش در این فاز ساخته نشده"), "", IF('تست کور'!I15="قبولی کامل (Pass)", 15, IF(OR('تست کور'!J15="عدم طرح سؤال در سناریوی مبهم", 'تست کور'!J15="طرح سؤال تکمیلی غلط و توهم اطلاعات", 'تست کور'!I15="سؤال تکمیلی نامربوط/توهم", 'تست کور'!I15="سکوت اشتباه در ابهام"), 0, IF(OR('تست کور'!J15="از قلم افتادن بخش دوم در جمله مرکب", 'تست کور'!I15="عدم تفکیک رویدادها"), 3, IF('تست کور'!I15="قبولی مشروط (Conditional)", 11, 8))))) | H15: =IF(C15="", "", C15+D15+E15+F15+G15) | I15: =IF(H15="", "در انتظار آزمون", IF(H15>=85, "قبولی ممتاز (Passed)", IF(H15>=70, "قبولی متوسط (Acceptable)", IF(H15>=50, "نیازمند بازآموزی (Retrain)", "مردود (Failed)")))) | J15: =IF('تست کور'!I15="", "تست نشده", 'تست کور'!I15)
A16: ='تست کور'!A16 | B16: ='تست کور'!B16 | C16: =IF(OR('تست کور'!I16="", 'تست کور'!I16="امتناع درست — قاعده‌اش در این فاز ساخته نشده"), "", IF('تست کور'!I16="قبولی کامل (Pass)", 25, IF('تست کور'!J16="خطا در تشخیص ماهیت رویداد", 0, IF('تست کور'!I16="قبولی مشروط (Conditional)", 20, 15)))) | D16: =IF(OR('تست کور'!I16="", 'تست کور'!I16="امتناع درست — قاعده‌اش در این فاز ساخته نشده"), "", IF('تست کور'!I16="قبولی کامل (Pass)", 25, IF(OR('تست کور'!J16="جابجایی یا اشتباه بدهکار/بستانکار", 'تست کور'!I16="خطا در تشخیص سرفصل"), 0, IF('تست کور'!I16="قبولی مشروط (Conditional)", 18, 10)))) | E16: =IF(OR('تست کور'!I16="", 'تست کور'!I16="امتناع درست — قاعده‌اش در این فاز ساخته نشده"), "", IF('تست کور'!I16="قبولی کامل (Pass)", 20, IF(OR('تست کور'!J16="استخراج اشتباه مبلغ یا ارقام", 'تست کور'!I16="خطا در استخراج مبلغ"), 0, IF('تست کور'!I16="قبولی مشروط (Conditional)", 15, 12)))) | F16: =IF(OR('تست کور'!I16="", 'تست کور'!I16="امتناع درست — قاعده‌اش در این فاز ساخته نشده"), "", IF('تست کور'!I16="قبولی کامل (Pass)", 15, IF('تست کور'!J16="عدم تشخیص سررسید یا طرف‌حساب", 0, IF('تست کور'!I16="قبولی مشروط (Conditional)", 11, 10)))) | G16: =IF(OR('تست کور'!I16="", 'تست کور'!I16="امتناع درست — قاعده‌اش در این فاز ساخته نشده"), "", IF('تست کور'!I16="قبولی کامل (Pass)", 15, IF(OR('تست کور'!J16="عدم طرح سؤال در سناریوی مبهم", 'تست کور'!J16="طرح سؤال تکمیلی غلط و توهم اطلاعات", 'تست کور'!I16="سؤال تکمیلی نامربوط/توهم", 'تست کور'!I16="سکوت اشتباه در ابهام"), 0, IF(OR('تست کور'!J16="از قلم افتادن بخش دوم در جمله مرکب", 'تست کور'!I16="عدم تفکیک رویدادها"), 3, IF('تست کور'!I16="قبولی مشروط (Conditional)", 11, 8))))) | H16: =IF(C16="", "", C16+D16+E16+F16+G16) | I16: =IF(H16="", "در انتظار آزمون", IF(H16>=85, "قبولی ممتاز (Passed)", IF(H16>=70, "قبولی متوسط (Acceptable)", IF(H16>=50, "نیازمند بازآموزی (Retrain)", "مردود (Failed)")))) | J16: =IF('تست کور'!I16="", "تست نشده", 'تست کور'!I16)
A17: ='تست کور'!A17 | B17: ='تست کور'!B17 | C17: =IF(OR('تست کور'!I17="", 'تست کور'!I17="امتناع درست — قاعده‌اش در این فاز ساخته نشده"), "", IF('تست کور'!I17="قبولی کامل (Pass)", 25, IF('تست کور'!J17="خطا در تشخیص ماهیت رویداد", 0, IF('تست کور'!I17="قبولی مشروط (Conditional)", 20, 15)))) | D17: =IF(OR('تست کور'!I17="", 'تست کور'!I17="امتناع درست — قاعده‌اش در این فاز ساخته نشده"), "", IF('تست کور'!I17="قبولی کامل (Pass)", 25, IF(OR('تست کور'!J17="جابجایی یا اشتباه بدهکار/بستانکار", 'تست کور'!I17="خطا در تشخیص سرفصل"), 0, IF('تست کور'!I17="قبولی مشروط (Conditional)", 18, 10)))) | E17: =IF(OR('تست کور'!I17="", 'تست کور'!I17="امتناع درست — قاعده‌اش در این فاز ساخته نشده"), "", IF('تست کور'!I17="قبولی کامل (Pass)", 20, IF(OR('تست کور'!J17="استخراج اشتباه مبلغ یا ارقام", 'تست کور'!I17="خطا در استخراج مبلغ"), 0, IF('تست کور'!I17="قبولی مشروط (Conditional)", 15, 12)))) | F17: =IF(OR('تست کور'!I17="", 'تست کور'!I17="امتناع درست — قاعده‌اش در این فاز ساخته نشده"), "", IF('تست کور'!I17="قبولی کامل (Pass)", 15, IF('تست کور'!J17="عدم تشخیص سررسید یا طرف‌حساب", 0, IF('تست کور'!I17="قبولی مشروط (Conditional)", 11, 10)))) | G17: =IF(OR('تست کور'!I17="", 'تست کور'!I17="امتناع درست — قاعده‌اش در این فاز ساخته نشده"), "", IF('تست کور'!I17="قبولی کامل (Pass)", 15, IF(OR('تست کور'!J17="عدم طرح سؤال در سناریوی مبهم", 'تست کور'!J17="طرح سؤال تکمیلی غلط و توهم اطلاعات", 'تست کور'!I17="سؤال تکمیلی نامربوط/توهم", 'تست کور'!I17="سکوت اشتباه در ابهام"), 0, IF(OR('تست کور'!J17="از قلم افتادن بخش دوم در جمله مرکب", 'تست کور'!I17="عدم تفکیک رویدادها"), 3, IF('تست کور'!I17="قبولی مشروط (Conditional)", 11, 8))))) | H17: =IF(C17="", "", C17+D17+E17+F17+G17) | I17: =IF(H17="", "در انتظار آزمون", IF(H17>=85, "قبولی ممتاز (Passed)", IF(H17>=70, "قبولی متوسط (Acceptable)", IF(H17>=50, "نیازمند بازآموزی (Retrain)", "مردود (Failed)")))) | J17: =IF('تست کور'!I17="", "تست نشده", 'تست کور'!I17)
A18: ='تست کور'!A18 | B18: ='تست کور'!B18 | C18: =IF(OR('تست کور'!I18="", 'تست کور'!I18="امتناع درست — قاعده‌اش در این فاز ساخته نشده"), "", IF('تست کور'!I18="قبولی کامل (Pass)", 25, IF('تست کور'!J18="خطا در تشخیص ماهیت رویداد", 0, IF('تست کور'!I18="قبولی مشروط (Conditional)", 20, 15)))) | D18: =IF(OR('تست کور'!I18="", 'تست کور'!I18="امتناع درست — قاعده‌اش در این فاز ساخته نشده"), "", IF('تست کور'!I18="قبولی کامل (Pass)", 25, IF(OR('تست کور'!J18="جابجایی یا اشتباه بدهکار/بستانکار", 'تست کور'!I18="خطا در تشخیص سرفصل"), 0, IF('تست کور'!I18="قبولی مشروط (Conditional)", 18, 10)))) | E18: =IF(OR('تست کور'!I18="", 'تست کور'!I18="امتناع درست — قاعده‌اش در این فاز ساخته نشده"), "", IF('تست کور'!I18="قبولی کامل (Pass)", 20, IF(OR('تست کور'!J18="استخراج اشتباه مبلغ یا ارقام", 'تست کور'!I18="خطا در استخراج مبلغ"), 0, IF('تست کور'!I18="قبولی مشروط (Conditional)", 15, 12)))) | F18: =IF(OR('تست کور'!I18="", 'تست کور'!I18="امتناع درست — قاعده‌اش در این فاز ساخته نشده"), "", IF('تست کور'!I18="قبولی کامل (Pass)", 15, IF('تست کور'!J18="عدم تشخیص سررسید یا طرف‌حساب", 0, IF('تست کور'!I18="قبولی مشروط (Conditional)", 11, 10)))) | G18: =IF(OR('تست کور'!I18="", 'تست کور'!I18="امتناع درست — قاعده‌اش در این فاز ساخته نشده"), "", IF('تست کور'!I18="قبولی کامل (Pass)", 15, IF(OR('تست کور'!J18="عدم طرح سؤال در سناریوی مبهم", 'تست کور'!J18="طرح سؤال تکمیلی غلط و توهم اطلاعات", 'تست کور'!I18="سؤال تکمیلی نامربوط/توهم", 'تست کور'!I18="سکوت اشتباه در ابهام"), 0, IF(OR('تست کور'!J18="از قلم افتادن بخش دوم در جمله مرکب", 'تست کور'!I18="عدم تفکیک رویدادها"), 3, IF('تست کور'!I18="قبولی مشروط (Conditional)", 11, 8))))) | H18: =IF(C18="", "", C18+D18+E18+F18+G18) | I18: =IF(H18="", "در انتظار آزمون", IF(H18>=85, "قبولی ممتاز (Passed)", IF(H18>=70, "قبولی متوسط (Acceptable)", IF(H18>=50, "نیازمند بازآموزی (Retrain)", "مردود (Failed)")))) | J18: =IF('تست کور'!I18="", "تست نشده", 'تست کور'!I18)
A19: ='تست کور'!A19 | B19: ='تست کور'!B19 | C19: =IF(OR('تست کور'!I19="", 'تست کور'!I19="امتناع درست — قاعده‌اش در این فاز ساخته نشده"), "", IF('تست کور'!I19="قبولی کامل (Pass)", 25, IF('تست کور'!J19="خطا در تشخیص ماهیت رویداد", 0, IF('تست کور'!I19="قبولی مشروط (Conditional)", 20, 15)))) | D19: =IF(OR('تست کور'!I19="", 'تست کور'!I19="امتناع درست — قاعده‌اش در این فاز ساخته نشده"), "", IF('تست کور'!I19="قبولی کامل (Pass)", 25, IF(OR('تست کور'!J19="جابجایی یا اشتباه بدهکار/بستانکار", 'تست کور'!I19="خطا در تشخیص سرفصل"), 0, IF('تست کور'!I19="قبولی مشروط (Conditional)", 18, 10)))) | E19: =IF(OR('تست کور'!I19="", 'تست کور'!I19="امتناع درست — قاعده‌اش در این فاز ساخته نشده"), "", IF('تست کور'!I19="قبولی کامل (Pass)", 20, IF(OR('تست کور'!J19="استخراج اشتباه مبلغ یا ارقام", 'تست کور'!I19="خطا در استخراج مبلغ"), 0, IF('تست کور'!I19="قبولی مشروط (Conditional)", 15, 12)))) | F19: =IF(OR('تست کور'!I19="", 'تست کور'!I19="امتناع درست — قاعده‌اش در این فاز ساخته نشده"), "", IF('تست کور'!I19="قبولی کامل (Pass)", 15, IF('تست کور'!J19="عدم تشخیص سررسید یا طرف‌حساب", 0, IF('تست کور'!I19="قبولی مشروط (Conditional)", 11, 10)))) | G19: =IF(OR('تست کور'!I19="", 'تست کور'!I19="امتناع درست — قاعده‌اش در این فاز ساخته نشده"), "", IF('تست کور'!I19="قبولی کامل (Pass)", 15, IF(OR('تست کور'!J19="عدم طرح سؤال در سناریوی مبهم", 'تست کور'!J19="طرح سؤال تکمیلی غلط و توهم اطلاعات", 'تست کور'!I19="سؤال تکمیلی نامربوط/توهم", 'تست کور'!I19="سکوت اشتباه در ابهام"), 0, IF(OR('تست کور'!J19="از قلم افتادن بخش دوم در جمله مرکب", 'تست کور'!I19="عدم تفکیک رویدادها"), 3, IF('تست کور'!I19="قبولی مشروط (Conditional)", 11, 8))))) | H19: =IF(C19="", "", C19+D19+E19+F19+G19) | I19: =IF(H19="", "در انتظار آزمون", IF(H19>=85, "قبولی ممتاز (Passed)", IF(H19>=70, "قبولی متوسط (Acceptable)", IF(H19>=50, "نیازمند بازآموزی (Retrain)", "مردود (Failed)")))) | J19: =IF('تست کور'!I19="", "تست نشده", 'تست کور'!I19)
A20: ='تست کور'!A20 | B20: ='تست کور'!B20 | C20: =IF(OR('تست کور'!I20="", 'تست کور'!I20="امتناع درست — قاعده‌اش در این فاز ساخته نشده"), "", IF('تست کور'!I20="قبولی کامل (Pass)", 25, IF('تست کور'!J20="خطا در تشخیص ماهیت رویداد", 0, IF('تست کور'!I20="قبولی مشروط (Conditional)", 20, 15)))) | D20: =IF(OR('تست کور'!I20="", 'تست کور'!I20="امتناع درست — قاعده‌اش در این فاز ساخته نشده"), "", IF('تست کور'!I20="قبولی کامل (Pass)", 25, IF(OR('تست کور'!J20="جابجایی یا اشتباه بدهکار/بستانکار", 'تست کور'!I20="خطا در تشخیص سرفصل"), 0, IF('تست کور'!I20="قبولی مشروط (Conditional)", 18, 10)))) | E20: =IF(OR('تست کور'!I20="", 'تست کور'!I20="امتناع درست — قاعده‌اش در این فاز ساخته نشده"), "", IF('تست کور'!I20="قبولی کامل (Pass)", 20, IF(OR('تست کور'!J20="استخراج اشتباه مبلغ یا ارقام", 'تست کور'!I20="خطا در استخراج مبلغ"), 0, IF('تست کور'!I20="قبولی مشروط (Conditional)", 15, 12)))) | F20: =IF(OR('تست کور'!I20="", 'تست کور'!I20="امتناع درست — قاعده‌اش در این فاز ساخته نشده"), "", IF('تست کور'!I20="قبولی کامل (Pass)", 15, IF('تست کور'!J20="عدم تشخیص سررسید یا طرف‌حساب", 0, IF('تست کور'!I20="قبولی مشروط (Conditional)", 11, 10)))) | G20: =IF(OR('تست کور'!I20="", 'تست کور'!I20="امتناع درست — قاعده‌اش در این فاز ساخته نشده"), "", IF('تست کور'!I20="قبولی کامل (Pass)", 15, IF(OR('تست کور'!J20="عدم طرح سؤال در سناریوی مبهم", 'تست کور'!J20="طرح سؤال تکمیلی غلط و توهم اطلاعات", 'تست کور'!I20="سؤال تکمیلی نامربوط/توهم", 'تست کور'!I20="سکوت اشتباه در ابهام"), 0, IF(OR('تست کور'!J20="از قلم افتادن بخش دوم در جمله مرکب", 'تست کور'!I20="عدم تفکیک رویدادها"), 3, IF('تست کور'!I20="قبولی مشروط (Conditional)", 11, 8))))) | H20: =IF(C20="", "", C20+D20+E20+F20+G20) | I20: =IF(H20="", "در انتظار آزمون", IF(H20>=85, "قبولی ممتاز (Passed)", IF(H20>=70, "قبولی متوسط (Acceptable)", IF(H20>=50, "نیازمند بازآموزی (Retrain)", "مردود (Failed)")))) | J20: =IF('تست کور'!I20="", "تست نشده", 'تست کور'!I20)
A21: ='تست کور'!A21 | B21: ='تست کور'!B21 | C21: =IF(OR('تست کور'!I21="", 'تست کور'!I21="امتناع درست — قاعده‌اش در این فاز ساخته نشده"), "", IF('تست کور'!I21="قبولی کامل (Pass)", 25, IF('تست کور'!J21="خطا در تشخیص ماهیت رویداد", 0, IF('تست کور'!I21="قبولی مشروط (Conditional)", 20, 15)))) | D21: =IF(OR('تست کور'!I21="", 'تست کور'!I21="امتناع درست — قاعده‌اش در این فاز ساخته نشده"), "", IF('تست کور'!I21="قبولی کامل (Pass)", 25, IF(OR('تست کور'!J21="جابجایی یا اشتباه بدهکار/بستانکار", 'تست کور'!I21="خطا در تشخیص سرفصل"), 0, IF('تست کور'!I21="قبولی مشروط (Conditional)", 18, 10)))) | E21: =IF(OR('تست کور'!I21="", 'تست کور'!I21="امتناع درست — قاعده‌اش در این فاز ساخته نشده"), "", IF('تست کور'!I21="قبولی کامل (Pass)", 20, IF(OR('تست کور'!J21="استخراج اشتباه مبلغ یا ارقام", 'تست کور'!I21="خطا در استخراج مبلغ"), 0, IF('تست کور'!I21="قبولی مشروط (Conditional)", 15, 12)))) | F21: =IF(OR('تست کور'!I21="", 'تست کور'!I21="امتناع درست — قاعده‌اش در این فاز ساخته نشده"), "", IF('تست کور'!I21="قبولی کامل (Pass)", 15, IF('تست کور'!J21="عدم تشخیص سررسید یا طرف‌حساب", 0, IF('تست کور'!I21="قبولی مشروط (Conditional)", 11, 10)))) | G21: =IF(OR('تست کور'!I21="", 'تست کور'!I21="امتناع درست — قاعده‌اش در این فاز ساخته نشده"), "", IF('تست کور'!I21="قبولی کامل (Pass)", 15, IF(OR('تست کور'!J21="عدم طرح سؤال در سناریوی مبهم", 'تست کور'!J21="طرح سؤال تکمیلی غلط و توهم اطلاعات", 'تست کور'!I21="سؤال تکمیلی نامربوط/توهم", 'تست کور'!I21="سکوت اشتباه در ابهام"), 0, IF(OR('تست کور'!J21="از قلم افتادن بخش دوم در جمله مرکب", 'تست کور'!I21="عدم تفکیک رویدادها"), 3, IF('تست کور'!I21="قبولی مشروط (Conditional)", 11, 8))))) | H21: =IF(C21="", "", C21+D21+E21+F21+G21) | I21: =IF(H21="", "در انتظار آزمون", IF(H21>=85, "قبولی ممتاز (Passed)", IF(H21>=70, "قبولی متوسط (Acceptable)", IF(H21>=50, "نیازمند بازآموزی (Retrain)", "مردود (Failed)")))) | J21: =IF('تست کور'!I21="", "تست نشده", 'تست کور'!I21)
